Workbook

Sheet 총계
J1: < 2014년 전국 극장 현황 >
N2: 2014. 12. 31 기준
A3: 지역 | B3: 2014년 극장 수 | C3: 2014년 스크린 수 | D3: 2014년 좌석 수 | E3: 2013년 극장 수 | F3: 전년 대비 극장 수 증감수 | G3: 전년 대비 극장 수 증감율 | H3: 2013년 스크린 수 | I3: 전년 대비 스크린 수 증감수 | J3: 전년 대비 스크린 수 증감율 | K3: 폐관 극장 수 | L3: 폐관 스크린 수 | M3: 필름 전용관수 | N3: 디지털 2D 상영관수 | O3: 3D 가능관수 | P3: IMAX 상영관 수 | Q3: 4D 상영관수
A4: 서울 | B4: 76 | C4: 469 | D4: 80334 | E4: 74 | F4: =B4-E4 -> 2 | G4: =(B4-E4)/E4 -> 0.027027027 | H4: 475 | I4: =C4-H4 -> -6 | J4: =(C4-H4)/H4 -> -0.012631579 | K4: 2 | L4: 14 | M4: =서울!I78 -> 0 | N4: 469 | O4: 218 | P4: 3 | Q4: 13
A5: 부산 | B5: 26 | C5: 193 | D5: 34596 | E5: 25 | F5: =B5-E5 -> 1 | G5: =(B5-E5)/E5 -> 0.04 | H5: 183 | I5: =C5-H5 -> 10 | J5: =(C5-H5)/H5 -> 0.054644809 | K5: 1 | L5: 7 | M5: =부산!I28 -> 0 | N5: 193 | O5: 78 | P5: 1 | Q5: 3
A6: 대구 | B6: 20 | C6: 132 | D6: 21187 | E6: 19 | F6: =B6-E6 -> 1 | G6: =(B6-E6)/E6 -> 0.052631579 | H6: 131 | I6: =C6-H6 -> 1 | J6: =(C6-H6)/H6 -> 0.0076335878 | K6: 0 | L6: 6 | M6: =대구!I22 -> 0 | N6: 132 | O6: 58 | P6: 1 | Q6: 1
A7: 인천 | B7: 19 | C7: 124 | D7: 19814 | E7: 17 | F7: =B7-E7 -> 2 | G7: =(B7-E7)/E7 -> 0.11764706 | H7: 111 | I7: =C7-H7 -> 13 | J7: =(C7-H7)/H7 -> 0.11711712 | K7: 0 | L7: 0 | M7: =인천!I21 -> 0 | N7: 124 | O7: 42 | P7: 1 | Q7: 1
A8: 광주 | B8: 14 | C8: 107 | D8: 18145 | E8: 14 | F8: =B8-E8 -> 0 | G8: =(B8-E8)/E8 -> 0 | H8: 107 | I8: =C8-H8 -> 0 | J8: =(C8-H8)/H8 -> 0 | K8: 0 | L8: 0 | M8: =광주!I16 -> 0 | N8: 107 | O8: 32 | P8: 1 | Q8: 2
A9: 대전 | B9: 9 | C9: 61 | D9: 10782 | E9: 9 | F9: =B9-E9 -> 0 | G9: =(B9-E9)/E9 -> 0 | H9: 61 | I9: =C9-H9 -> 0 | J9: =(C9-H9)/H9 -> 0 | K9: 1 | L9: 5 | M9: =대전!I11 -> 0 | N9: 61 | O9: 24 | P9: 1 | Q9: 1
A10: 울산 | B10: 5 | C10: 37 | D10: 6022 | E10: 5 | F10: =B10-E10 -> 0 | G10: =(B10-E10)/E10 -> 0 | H10: 36 | I10: =C10-H10 -> 1 | J10: =(C10-H10)/H10 -> 0.027777778 | K10: 0 | L10: 0 | M10: =울산!I7 -> 0 | N10: 37 | O10: 17 | P10: 1 | Q10: 2
A11: 경기 | B11: 81 | C11: 515 | D11: 80661 | E11: 73 | F11: =B11-E11 -> 8 | G11: =(B11-E11)/E11 -> 0.10958904 | H11: 486 | I11: =C11-H11 -> 29 | J11: =(C11-H11)/H11 -> 0.059670782 | K11: 2 | L11: 15 | M11: =경기!I83 -> 0 | N11: 515 | O11: 192 | P11: 3 | Q11: 6
A12: 강원 | B12: 11 | C12: 65 | D12: 9866 | E12: 9 | F12: =B12-E12 -> 2 | G12: =(B12-E12)/E12 -> 0.22222222 | H12: 62 | I12: =C12-H12 -> 3 | J12: =(C12-H12)/H12 -> 0.048387097 | K12: 0 | L12: 0 | M12: =강원!I13 -> 0 | N12: 65 | O12: 24 | P12: 1 | Q12: 0
A13: 충북 | B13: 10 | C13: 80 | D13: 14048 | E13: 9 | F13: =B13-E13 -> 1 | G13: =(B13-E13)/E13 -> 0.11111111 | H13: 72 | I13: =C13-H13 -> 8 | J13: =(C13-H13)/H13 -> 0.11111111 | K13: 0 | L13: 0 | M13: =충북!I12 -> 0 | N13: 80 | O13: 23 | P13: 0 | Q13: 1
A14: 충남 | B14: 13 | C14: 82 | D14: 11651 | E14: 13 | F14: =B14-E14 -> 0 | G14: =(B14-E14)/E14 -> 0 | H14: 78 | I14: =C14-H14 -> 4 | J14: =(C14-H14)/H14 -> 0.051282051 | K14: 2 | L14: 9 | M14: =충남!I15 -> 0 | N14: 82 | O14: 39 | P14: 0 | Q14: 1
A15: 전북 | B15: 19 | C15: 93 | D15: 14429 | E15: 15 | F15: =B15-E15 -> 4 | G15: =(B15-E15)/E15 -> 0.26666667 | H15: 77 | I15: =C15-H15 -> 16 | J15: =(C15-H15)/H15 -> 0.20779221 | K15: 1 | L15: 4 | M15: =전북!I21 -> 0 | N15: 93 | O15: 33 | P15: 1 | Q15: 0
A16: 전남 | B16: 10 | C16: 63 | D16: 8977 | E16: 8 | F16: =B16-E16 -> 2 | G16: =(B16-E16)/E16 -> 0.25 | H16: 52 | I16: =C16-H16 -> 11 | J16: =(C16-H16)/H16 -> 0.21153846 | K16: 0 | L16: 0 | M16: =전남!I12 -> 0 | N16: 63 | O16: 21 | P16: 0 | Q16: 0
A17: 경북 | B17: 16 | C17: 94 | D17: 15536 | E17: 16 | F17: =B17-E17 -> 0 | G17: =(B17-E17)/E17 -> 0 | H17: 94 | I17: =C17-H17 -> 0 | J17: =(C17-H17)/H17 -> 0 | K17: 0 | L17: 0 | M17: =경북!I18 -> 0 | N17: 94 | O17: 20 | P17: 0 | Q17: 0
A18: 경남 | B18: 21 | C18: 133 | D18: 21927 | E18: 21 | F18: =B18-E18 -> 0 | G18: =(B18-E18)/E18 -> 0 | H18: 128 | I18: =C18-H18 -> 5 | J18: =(C18-H18)/H18 -> 0.0390625 | K18: 1 | L18: 3 | M18: =경남!I23 -> 0 | N18: 133 | O18: 46 | P18: 1 | Q18: 1
A19: 제주 | B19: 6 | C19: 33 | D19: 4386 | E19: 6 | F19: =B19-E19 -> 0 | G19: =(B19-E19)/E19 -> 0 | H19: 31 | I19: =C19-H19 -> 2 | J19: =(C19-H19)/H19 -> 0.064516129 | K19: 0 | L19: 3 | M19: =제주!I8 -> 0 | N19: 33 | O19: 9 | P19: 0 | Q19: 0
A20: 지방 합계 | B20: =SUM(B5:B19) -> 280 | C20: 1812 | D20: 292027 | E20: =SUM(E5:E19) -> 259 | F20: =B20-E20 -> 21 | G20: =(B20-E20)/E20 -> 0.081081081 | H20: =SUM(H5:H19) -> 1709 | I20: =C20-H20 -> 103 | J20: =(C20-H20)/H20 -> 0.060269163 | K20: =SUM(K5:K19) -> 8 | L20: =SUM(L5:L19) -> 52 | M20: =SUM(M5:M19) -> 0 | N20: 1812 | O20: 658 | P20: 12 | Q20: 19
A21: 총계 | B21: =B4+B20 -> 356 | C21: 2281 | D21: 372361 | E21: =SUM(E4:E19) -> 333 | F21: =B21-E21 -> 23 | G21: =(B21-E21)/E21 -> 0.069069069 | H21: =H4+H20 -> 2184 | I21: =C21-H21 -> 97 | J21: =(C21-H21)/H21 -> 0.044413919 | K21: =SUM(K4:K19) -> 10 | L21: =SUM(L4:L19) -> 66 | M21: =M20+M4 -> 0 | N21: 2281 | O21: 876 | P21: 15 | Q21: 32
A23: * 집계 대상 극장은 전국 상설 영화관으로, 특수 목적의 비상설 상영 시설 및 자동차극장은 제외함 (영비법 제2조*상세 하단 참고)
A24: * 기준일 당시 휴관 및 폐관극장은 극장 수 합계에서 제외
A25: * 각 지방자치단체 폐관 신고를 한 극장은 폐관으로 처리함(영비법 제36조*상세 하단 참고)
A26: * 3대 멀티플렉스 내 상호변경은 폐관극장에 포함하지 않음(예_CGV 독산 -> 롯데시네마 독산으로 전환시 CGV 독산은 폐관극장으로 간주하지 않음)
A27: * 개별극장이 3대 멀티플렉스 체인극장으로 전환시에는 폐관극장으로 간주함 (예_씨네위 -> CGV 유성노은으로 전환시 씨네위는 폐관극장으로 간주함)
A29: * 영화 및 비디오물의 진흥에 관한 법률 참고
A30: * 법 제2조(정의) : “영화상영관”은 영리를 목적으로 영화를 상영하는 장소 또는 시설(단, 비상설상영장은 제외함)
A31: * 시행령 제2조(비상설상영장) : 영화상영일수가 120일 이내이고 계속상영기간이 30일 이내인 영화상영 장소 또는 시설
A32: * 법 제36조(영화상영관의 등록) : “영화상영관”은 소재지를 관할하는 시군구에 영화상영관 등록을 하여야 함

Sheet 서울
A1: 번호 | B1: 광역단체 | C1: 기초단체 | D1: 영화관명 | E1: 대기업 운영 여부 | F1: 소재지 | G1: 총 스크린 수 | H1: 총 좌석수 | I1: 필름 전용관수 | J1: 디지털 2D 상영관수 | K1: 3D 가능관수 | L1: IMAX 상영관 수 | M1: 4D 상영관수 | N1: 특별관 운영 여부 | O1: 전화번호(02) | P1: 홈페이지 | Q1: 개관일 | R1: 비고
A2: 1 | B2: 서울시 | C2: 강남구 | D2: CGV 강남 | E2: 직영 | F2: 강남구 강남대로 438 (역삼동 814-6 스타플렉스) | G2: 6 | H2: 874 | I2: =G2-J2 -> 0 | J2: 6 | K2: 4 | L2: 0 | M2: 0 | N2: Sweetbox, ScreenX, Veatbox | O2: 1544-1122 | P2: www.cgv.co.kr | Q2: 39121
A3: 2 | B3: 서울시 | C3: 강남구 | D3: CGV 압구정 | E3: 직영 | F3: 강남구 압구정로 30길 45 (신사동 603-2) | G3: 8 | H3: 1170 | I3: =G3-J3 -> 0 | J3: 8 | K3: 5 | L3: 0 | M3: 0 | N3: Sweetbox, Cine de Chef, CGV 아트하우스, Veatbox | O3: 1544-1122 | P3: www.cgv.co.kr | Q3: 38779
A4: 3 | B4: 서울시 | C4: 강남구 | D4: CGV 청담씨네시티 | E4: 직영 | F4: 강남구 도산대로 323 (신사동 651-21) | G4: 5 | H4: 806 | I4: 0 | J4: 5 | K4: 5 | L4: 0 | M4: 1 | N4: Sweetbox, 4DX, Beats br dr.dre, The Private Cinema, ScreenX, SoundX | O4: 1544-1122 | P4: www.cgv.co.kr | Q4: 40828
A5: 4 | B5: 서울시 | C5: 강남구 | D5: 롯데시네마 씨티(강남) | E5: 위탁 | F5: 강남구 강남대로 422 (역삼동 816-7) | G5: 4 | H5: 719 | I5: =G5-J5 -> 0 | J5: 4 | K5: 2 | L5: 0 | M5: 0 | N5: ~ | O5: 1544-8855 | P5: www.lottecinema.co.kr | Q5: 40696
A6: 5 | B6: 서울시 | C6: 강남구 | D6: 메가박스 코엑스 | E6: 직영 | F6: 강남구 봉은사로 524 코엑스몰 B1 (삼성동 159) | G6: 16 | H6: 3541 | I6: =G6-J6 -> 0 | J6: 16 | K6: 3 | L6: 0 | M6: 0 | N6: Boutique M, M2, 프리미엄 | O6: 1544-0070 | P6: www.megabox.co.kr | Q6: 36659
A7: 6 | B7: 서울시 | C7: 강남구 | D7: 롯데시네마 브로드웨이(신사) | E7: 위탁 | F7: 강남구 도산대로 8길 8 (논현동 3-5) | G7: 5 | H7: 500 | I7: 0 | J7: 5 | K7: 2 | L7: 0 | M7: 0 | N7: 3관 인디플러스 | O7: 1544-8855 | P7: www.lottecinema.co.kr | Q7: 41376 | R7: (구)브로드웨이 극장
A8: 7 | B8: 서울시 | C8: 강남구 | D8: 인디플러스 | E8: ~ | F8: 강남구 도산대로 8길 8 | G8: 1 | H8: 70 | I8: 0 | J8: 1 | K8: 0 | L8: 0 | M8: 0 | N8: ~ | O8: 3447-0650 | P8: www.indieplus.or.kr | Q8: 40652 | R8: 영진위 독립영화전용관
A9: 8 | B9: 서울시 | C9: 강남구 | D9: 조이앤시네마 | E9: ~ | F9: 강남구 압구정로 10길 9 | G9: 1 | H9: 59 | I9: 0 | J9: 1 | K9: 1 | L9: 0 | M9: 0 | N9: ~ | O9: 070-8233-4321 | Q9: 41915
A10: 9 | B10: 서울시 | C10: 강동구 | D10: CGV 강동 | E10: 위탁 | F10: 강동구 성내로 48 (성내동 549-1) | G10: 12 | H10: 1965 | I10: =G10-J10 -> 0 | J10: 12 | K10: 2 | L10: 0 | M10: 0 | N10: ~ | O10: 1544-1122 | P10: www.cgv.co.kr | Q10: 39195
A11: 10 | B11: 서울시 | C11: 강동구 | D11: 롯데시네마 강동 | E11: 위탁 | F11: 강동구 천호옛길 85 (성내동 44-1) | G11: 10 | H11: 1998 | I11: =G11-J11 -> 0 | J11: 10 | K11: 5 | L11: 0 | M11: 0 | N11: ~ | O11: 1544-8855 | P11: www.lottecinema.co.kr | Q11: 39562
A12: 11 | B12: 서울시 | C12: 강북구 | D12: CGV 미아 | E12: 직영 | F12: 강북구 도봉로 34, 9층 (미아동 35-4 트레지오 쇼핑몰 9층) | G12: 6 | H12: 721 | I12: =G12-J12 -> 0 | J12: 6 | K12: 3 | L12: 0 | M12: 0 | N12: Sweetbox, Veatbox | O12: 1544-1122 | P12: www.cgv.co.kr | Q12: 39173
A13: 12 | B13: 서울시 | C13: 강북구 | D13: 메가박스 수유 | E13: 위탁 | F13: 강북구 도봉로 399 (수유동 168-12) | G13: 9 | H13: 1167 | I13: 0 | J13: 9 | K13: 2 | L13: 0 | M13: 0 | N13: ~ | O13: 1544-0070 | P13: www.megabox.co.kr | Q13: 40964
A14: 13 | B14: 서울시 | C14: 강서구 | D14: 롯데시네마 김포공항 | E14: 직영 | F14: 강서구 하늘길 77 롯데몰 (방화동 하늘길 38) | G14: 10 | H14: 2127 | I14: =G14-J14 -> 0 | J14: 10 | K14: 7 | L14: 0 | M14: 1 | N14: 샤롯데, 수퍼4D | O14: 1544-8855 | P14: www.lottecinema.co.kr | Q14: 40865
A15: 14 | B15: 서울시 | C15: 관악구 | D15: 롯데시네마 서울대입구 | E15: 직영 | F15: 관악구 남부순환로 1820 (봉천동 862-1 에그옐로우 10층) | G15: 5 | H15: 676 | I15: 0 | J15: 5 | K15: 2 | L15: 0 | M15: 0 | N15: ~ | O15: 1544-8855 | P15: www.lottecinema.co.kr | Q15: 41272 | R15: (구)메가박스 서울대
A16: 15 | B16: 서울시 | C16: 관악구 | D16: 롯데시네마 신림 | E16: 직영 | F16: 관악구 신림로 330, 10층 (신림동 1641-2 포도몰 10층) | G16: 8 | H16: 1477 | I16: =G16-J16 -> 0 | J16: 8 | K16: 6 | L16: 0 | M16: 0 | N16: ~ | O16: 1544-8855 | P16: www.lottecinema.co.kr | Q16: 39873
A17: 16 | B17: 서울시 | C17: 광진구 | D17: CGV 강변 | E17: 직영 | F17: 광진구 광나루로 56길 85 (구의동 546-4 테크노마트 10층) | G17: 11 | H17: 1663 | I17: =G17-J17 -> 0 | J17: 11 | K17: 5 | L17: 0 | M17: 1 | N17: Sweetbox, 4DX, CGV 아트하우스, ScreenX, Veatbox | O17: 1544-1122 | P17: www.cgv.co.kr | Q17: 35889
A18: 17 | B18: 서울시 | C18: 광진구 | D18: CGV 군자 | E18: 위탁 | F18: 광진구 능동로 289 (군자동 477-12) | G18: 9 | H18: 1197 | I18: 0 | J18: 9 | K18: 0 | L18: 0 | M18: 0 | N18: ~ | O18: 1544-1122 | P18: www.cgv.co.kr | Q18: 40022
A19: 18 | B19: 서울시 | C19: 광진구 | D19: KU 시네마테크 | E19: ~ | F19: 광진구 능동로 120 건국대학요 예술문화대학 B108 (화양동 1번지) | G19: 1 | H19: 152 | I19: =G19-J19 -> 0 | J19: 1 | K19: 0 | L19: 0 | M19: 0 | N19: ~ | O19: 446-6579 | P19: www.kucine.kr | Q19: 40554 | R19: 건국대학교
A20: 19 | B20: 서울시 | C20: 광진구 | D20: 롯데시네마 건대입구 | E20: 직영 | F20: 광진구 아차산로 272 (자양동 227-7번지 스타시티 2층) | G20: 12 | H20: 2134 | I20: 0 | J20: 12 | K20: 8 | L20: 0 | M20: 0 | N20: 샤롯데, 수퍼바이브, 아르떼 | O20: 1544-8855 | P20: www.lottecinema.co.kr | Q20: 39109
A21: 20 | B21: 서울시 | C21: 구로구 | D21: CGV 구로 | E21: 직영 | F21: 구로구 구로중앙로 152 (구로동 573 애경백화점 5층) | G21: 10 | H21: 1830 | I21: =G21-J21 -> 0 | J21: 10 | K21: 5 | L21: 0 | M21: 0 | N21: Sweetbox, CGV 아트하우스, ScreenX, Veatbox | O21: 1544-1122 | P21: www.cgv.co.kr | Q21: 37279
A22: 21 | B22: 서울시 | C22: 구로구 | D22: CGV 신도림 | E22: 위탁 | F22: 구로구 새말로 12층 (구로동 3-25번지 테크노 마트 12층) | G22: 10 | H22: 1486 | I22: =G22-J22 -> 0 | J22: 10 | K22: 3 | L22: 0 | M22: 0 | N22: Sweetbox, Premium | O22: 1544-1122 | P22: www.cgv.co.kr | Q22: 39401
A23: 22 | B23: 서울시 | C23: 구로구 | D23: 롯데시네마 신도림(디큐브) | E23: 직영 | F23: 구로구 경인로 662 디큐브시티 7층 (신도림동 692) | G23: 5 | H23: 537 | I23: 0 | J23: 5 | K23: 2 | L23: 0 | M23: 0 | N23: 씨네커플, 아르떼 | O23: 1544-8855 | P23: www.lottecinema.co.kr | Q23: 41527
A24: 23 | B24: 서울시 | C24: 금천구 | D24: 롯데시네마 가산디지털 | E24: 직영 | F24: 금천구 디지털로 10길 9 현대아울렛쇼핑몰 (가산동) | G24: 6 | H24: 1054 | I24: 0 | J24: 6 | K24: 3 | L24: 0 | M24: 1 | N24: 수퍼4D, 수퍼바이브 | O24: 1544-8855 | P24: www.lottecinema.co.kr | Q24: 41347
A25: 24 | B25: 서울시 | C25: 금천구 | D25: 롯데시네마 독산 | E25: 직영 | F25: 금천구 시흥대로 399 시티렉스 6층 | G25: 8 | H25: 1606 | I25: 0 | J25: 8 | K25: 3 | L25: 0 | M25: 0 | N25: ~ | O25: 1544-8855 | P25: www.lottecinema.co.kr | Q25: 41950 | R25: (구)CGV 독산
A26: 25 | B26: 서울시 | C26: 노원구 | D26: CGV 중계 | E26: 직영 | F26: 노원구 동일로 204가길 12, 8층 (중계동 509-2) | G26: 7 | H26: 1179 | I26: 0 | J26: 7 | K26: 3 | L26: 0 | M26: 0 | N26: ScreenX | O26: 1544-1122 | P26: www.cgv.co.kr | Q26: 41389
A27: 26 | B27: 서울시 | C27: 노원구 | D27: CGV 하계 | E27: 직영 | F27: 노원구 섬밭로 258 지하 1층 (중계동 506-1 건영백화점 지하1층) | G27: 4 | H27: 917 | I27: 0 | J27: 4 | K27: 3 | L27: 0 | M27: 0 | N27: CINE KIDS | O27: 1544-1122 | P27: www.cgv.co.kr | Q27: 41529 | R27: (구)프리머스 노원
A28: 27 | B28: 서울시 | C28: 노원구 | D28: 롯데시네마 노원 | E28: 직영 | F28: 노원구 동일로 1414 롯데백화점 10층 (상계동 713) | G28: 10 | H28: 1758 | I28: 0 | J28: 10 | K28: 9 | L28: 0 | M28: 1 | N28: 수퍼4D, 씨네커플 | O28: 1544-8855 | P28: www.lottecinema.co.kr | Q28: 38679
A29: 28 | B29: 서울시 | C29: 동대문구 | D29: 롯데시네마 장안 | E29: 위탁 | F29: 동대문구 답십리로 288 바우하우스 11층 (장안동 368-1) | G29: 7 | H29: 1084 | I29: 0 | J29: 7 | K29: 2 | L29: 0 | M29: 0 | N29: ~ | O29: 1544-8855 | P29: www.lottecinema.co.kr | Q29: 41265
A30: 29 | B30: 서울시 | C30: 동대문구 | D30: 롯데시네마 청량리 | E30: 직영 | F30: 동대문구 왕산로 214 (전농동) | G30: 8 | H30: 1678 | I30: =G30-J30 -> 0 | J30: 8 | K30: 4 | L30: 0 | M30: 1 | N30: 수퍼4D | O30: 1544-8855 | P30: www.lottecinema.co.kr | Q30: 40410
A31: 30 | B31: 서울시 | C31: 동작구 | D31: 메가박스 이수 | E31: 직영 | F31: 동작구 동작대로 89 골든시네마타워 7층 (사당1동 147-53) | G31: 6 | H31: 816 | I31: 0 | J31: 6 | K31: 2 | L31: 0 | M31: 0 | N31: ~ | O31: 1544-0070 | P31: www.megabox.co.kr | Q31: 39219
A32: 31 | B32: 서울시 | C32: 동작구 | D32: 아트나인 | E32: ~ | F32: 동작구 동작대로 89 골든시네마 12층 | G32: 2 | H32: 150 | I32: 0 | J32: 2 | K32: 1 | L32: 0 | M32: 0 | N32: ~ | O32: 1544-0070 | P32: www.megabox.co.kr | Q32: 41275 | R32: 메가박스와 전산망 공유
A33: 32 | B33: 서울시 | C33: 마포구 | D33: CGV 상암 | E33: 직영 | F33: 마포구 월드컵로 240, 1층 (성산동 515 월드컵쇼핑몰1층) | G33: 10 | H33: 1688 | I33: =G33-J33 -> 0 | J33: 10 | K33: 5 | L33: 1 | M33: 1 | N33: IMAX, SweetBox, ScreenX, 4DX, CGV 아트하우스, Gold Class | O33: 1544-1122 | P33: www.cgv.co.kr | Q33: 37762
A34: 33 | B34: 서울시 | C34: 마포구 | D34: CGV 홍대 | E34: 직영 | F34: 마포구 양화로 153 (동교동) 3층 | G34: 6 | H34: 876 | I34: 0 | J34: 6 | K34: 3 | L34: 0 | M34: 0 | N34: ~ | O34: 1544-1122 | P34: www.cgv.co.kr | Q34: 41914
A35: 34 | B35: 서울시 | C35: 마포구 | D35: 롯데시네마 누리꿈(상암) | E35: 직영 | F35: 마포구 월드컵북로 396 (상암동 1605 누리꿈스퀘어빌딩 디지털파빌리온 4층) | G35: 2 | H35: 224 | I35: 0 | J35: 2 | K35: 1 | L35: 0 | M35: 0 | N35: ~ | O35: 1544-8855 | P35: www.lottecinema.co.kr | Q35: 40297
A36: 35 | B36: 서울시 | C36: 마포구 | D36: 롯데시네마 합정 | E36: 직영 | F36: 마포구 양화로 45 메세나폴리스 2층 (합정동 481-1) | G36: 4 | H36: 689 | I36: 0 | J36: 4 | K36: 2 | L36: 0 | M36: 0 | N36: ~ | O36: 1544-8855 | P36: www.lottecinema.co.kr | Q36: 41109
A37: 36 | B37: 서울시 | C37: 마포구 | D37: 롯데시네마 홍대입구 | E37: 직영 | F37: 마포구 양화로 176 와이즈파크 8층 (동교동166-6번지) | G37: 6 | H37: 1104 | I37: =G37-J37 -> 0 | J37: 6 | K37: 4 | L37: 0 | M37: 0 | N37: ~ | O37: 1544-8855 | P37: www.lottecinema.co.kr | Q37: 39448
A38: 37 | B38: 서울시 | C38: 마포구 | D38: 시네마상상마당 | E38: ~ | F38: 마포구 어울마당로 65 지하4층 (서교동 367-5) | G38: 1 | H38: 77 | I38: =G38-J38 -> 0 | J38: 1 | K38: 0 | L38: 0 | M38: 0 | N38: ~ | O38: 330-6200 | P38: cinema.sangsangmadang.com | Q38: 2007-09-00
A39: 38 | B39: 서울시 | C39: 서대문구 | D39: CGV 신촌아트레온 | E39: 직영 | F39: 서대문구 신촌로 129, 2층 (창천동 20-24, 20-25) | G39: 9 | H39: 1468 | I39: 0 | J39: 9 | K39: 5 | L39: 0 | M39: 1 | N39: 4DX, CGV 아트하우스, Premium, ScreenX | O39: 1544-1122 | P39: www.cgv.co.kr | Q39: 41445 | R39: (구)아트레온
A40: 39 | B40: 서울시 | C40: 서대문구 | D40: 메가박스 신촌 | E40: 직영 | F40: 서대문구 신촌역로 30 밀리오레 5층 (신촌동 74-12) | G40: 8 | H40: 1541 | I40: =G40-J40 -> 0 | J40: 8 | K40: 2 | L40: 0 | M40: 0 | N40: 1관 M관 | O40: 1544-0070 | P40: www.megabox.co.kr | Q40: 38982
...

Sheet 부산
A1: 번호 | B1: 광역단체 | C1: 기초단체 | D1: 영화관명 | E1: 대기업 운영 여부 | F1: 소재지 | G1: 총스크린수 | H1: 총좌석수 | I1: 필름 전용관수 | J1: 디지털 2D 상영관수 | K1: 3D 가능관수 | L1: IMAX 상영관 수 | M1: 4D 상영관수 | N1: 특별관 운영 여부 | O1: 전화번호(051) | P1: 홈페이지 | Q1: 개관일 | R1: 비고
A2: 1 | B2: 부산시 | C2: 금정구 | D2: CGV 부산대 | E2: 위탁 | F2: 금정구 장전로 12번길 55 (장전동 292-4) | G2: 7 | H2: 1094 | I2: =G2-J2 -> 0 | J2: 7 | K2: 2 | L2: 0 | M2: 0 | N2: ~ | O2: 1544-1122 | P2: www.cgv.co.kr | Q2: 40666
A3: 2 | B3: 부산시 | C3: 기장군 | D3: 롯데시네마 동부산 | E3: 직영 | F3: 기장군 기장해안로 147 동부산롯데몰 3층 | G3: 6 | H3: 1014 | I3: 0 | J3: 6 | K3: 2 | L3: 0 | M3: 0 | N3: ~ | O3: 1544-8855 | P3: www.lottecinema.co.kr | Q3: 41996
A4: 3 | B4: 부산시 | C4: 남구 | D4: CGV 대연 | E4: 직영 | F4: 남구 수영로 305, 5층 (대연동 73-15번지 스파크 5층) | G4: 8 | H4: 1065 | I4: =G4-J4 -> 0 | J4: 8 | K4: 4 | L4: 0 | M4: 0 | N4: Sweetbox, Veatbox | O4: 1544-1122 | P4: www.cgv.co.kr | Q4: 39337
A5: 4 | B5: 부산시 | C5: 남구 | D5: 국도예술관 | E5: ~ | F5: 남구 유엔평화로 70번길 23 (대연4동 965-2) | G5: 1 | H5: 143 | I5: 0 | J5: 1 | K5: 0 | L5: 0 | M5: 0 | N5: ~ | O5: 245-5441 | P5: cafe.naver.com/gukdo | Q5: 39633
A6: 5 | B6: 부산시 | C6: 동래구 | D6: CGV 동래 | E6: 직영 | F6: 동래구 중앙대로 1523, 6층 (온천동 153-8 SK허브스카이 6층) | G6: 9 | H6: 1631 | I6: =G6-J6 -> 0 | J6: 9 | K6: 4 | L6: 0 | M6: 0 | N6: Sweetbox, Veatbox | O6: 1544-1122 | P6: www.cgv.co.kr | Q6: 39015
A7: 6 | B7: 부산시 | C7: 동래구 | D7: 롯데시네마 동래 | E7: 직영 | F7: 동래구 중앙대로 1393 | G7: 9 | H7: 1466 | I7: =G7-J7 -> 0 | J7: 9 | K7: 6 | L7: 0 | M7: 0 | N7: 씨네커플 | O7: 1544-8855 | P7: www.lottecinema.co.kr | Q7: 39600
A8: 7 | B8: 부산시 | C8: 부산진구 | D8: CGV 대한 | E8: 직영 | F8: 부산진구 중앙대로 692번길 16, 4층 (부전동 199 대한프라자 4층) | G8: 4 | H8: 661 | I8: =G8-J8 -> 0 | J8: 4 | K8: 0 | L8: 0 | M8: 0 | N8: Sweetbox | O8: 1544-1122 | P8: www.cgv.co.kr | Q8: 36876
A9: 8 | B9: 부산시 | C9: 부산진구 | D9: CGV 서면 | E9: 직영 | F9: 부산진구 동천로 4, 6층 (전포동 892-20 지오플레이스 6층) | G9: 12 | H9: 2135 | I9: =G9-J9 -> 0 | J9: 12 | K9: 5 | L9: 1 | M9: 1 | N9: IMAX, CGV 아트하우스 | O9: 1544-1122 | P9: www.cgv.co.kr | Q9: 36677
A10: 9 | B10: 부산시 | C10: 부산진구 | D10: 롯데시네마 부산본점(백화점) | E10: 직영 | F10: 부산진구 가야대로 772 롯데백화점 10층 (부전동 503-15) | G10: 11 | H10: 1928 | I10: =G10-J10 -> 0 | J10: 11 | K10: 9 | L10: 0 | M10: 0 | N10: 수퍼사운드, 씨네커플 | O10: 1544-8855 | P10: www.lottecinema.co.kr | Q10: 37058
A11: 10 | B11: 부산시 | C11: 부산진구 | D11: 롯데시네마 서면(디시티) | E11: 직영 | F11: 부산진구 동천로 92, 6층 (전포동 668-1번지) | G11: 7 | H11: 1409 | I11: =G11-J11 -> 0 | J11: 7 | K11: 2 | L11: 0 | M11: 0 | N11: ~ | O11: 1544-8855 | P11: www.lottecinema.co.kr | Q11: 40422
A12: 11 | B12: 부산시 | C12: 부산진구 | D12: 메가박스 서면 | E12: 위탁 | F12: 부산진구 서면로 39 효성엑센시티 8층 (부전동 521-1) | G12: 6 | H12: 812 | I12: =G12-J12 -> 0 | J12: 6 | K12: 3 | L12: 0 | M12: 0 | N12: ~ | O12: 1544-0070 | P12: www.megabox.co.kr | Q12: 38960
A13: 12 | B13: 부산시 | C13: 북구 | D13: CGV 화명 | E13: 직영 | F13: 북구 화명대로 16 (화명동 2275-1 센추리빌딩) | G13: 9 | H13: 846 | I13: 0 | J13: 9 | K13: 2 | L13: 0 | M13: 0 | N13: ~ | O13: 1544-1122 | P13: www.cgv.co.kr | Q13: 37729 | R13: (구)프리머스 화명
A14: 13 | B14: 부산시 | C14: 북구 | D14: 메가박스 덕천 | E14: 위탁 | F14: 북구 만덕대로 23 뉴코아아울렛 7~10층 | G14: 9 | H14: 1180 | I14: 0 | J14: 9 | K14: 1 | L14: 0 | M14: 0 | N14: Table M관 | O14: 1544-0070 | P14: www.megabox.co.kr | Q14: 41393 | R14: (구)프리머스 덕천
A15: 14 | B15: 부산시 | C15: 사상구 | D15: 롯데시네마 사상(애플아울렛) | E15: 직영 | F15: 사상구 사상로 201 애플아울렛 본관 3~4층 (괘법동 533-1) | G15: 7 | H15: 1520 | I15: =G15-J15 -> 0 | J15: 7 | K15: 5 | L15: 0 | M15: 0 | N15: ~ | O15: 1544-8855 | P15: www.lottecinema.co.kr | Q15: 38365
A16: 15 | B16: 부산시 | C16: 연제구 | D16: CGV 아시아드 | E16: 직영 | F16: 연제구 종합운동장로 7 (거제2동 1208번지 홈플러스) | G16: 8 | H16: 1315 | I16: =G16-J16 -> 0 | J16: 8 | K16: 3 | L16: 0 | M16: 0 | N16: ~ | O16: 1544-1122 | P16: www.cgv.co.kr | Q16: 38004 | R16: 09년 3월 CGV 아시아드로 상호변경
A17: 16 | B17: 부산시 | C17: 중구 | D17: CGV 남포 | E17: 위탁 | F17: 중구 비프광장로 18 (남포동 6가 92-1 국도타운 6층) | G17: 2 | H17: 516 | I17: 0 | J17: 2 | K17: 0 | L17: 0 | M17: 0 | N17: ~ | O17: 1544-1122 | P17: www.cgv.co.kr | Q17: 37205
A18: 17 | B18: 부산시 | C18: 중구 | D18: 대영시네마 | E18: ~ | F18: 중구 비프광장로 37 (남포동 5가 12-1) | G18: 8 | H18: 1802 | I18: 0 | J18: 8 | K18: 2 | L18: 0 | M18: 0 | N18: ~ | O18: 247-1384 | P18: www.daeyoungcinema.com | Q18: 36357
A19: 18 | B19: 부산시 | C19: 중구 | D19: 메가박스 부산극장 | E19: 위탁 | F19: 중구 비프광장로 36 (남포동 5가 18) | G19: 8 | H19: 2264 | I19: =G19-J19 -> 0 | J19: 8 | K19: 2 | L19: 0 | M19: 0 | N19: ~ | O19: 1544-0070 | P19: www.megabox.co.kr | Q19: 39055 | R19: (구)부산극장
A20: 19 | B20: 부산시 | C20: 중구 | D20: 아트씨어터 씨앤씨 | E20: ~ | F20: 중구 중구로 71 가톨릭센터 1층 (대청동4가 81-1) | G20: 1 | H20: 200 | I20: 0 | J20: 1 | K20: 0 | L20: 0 | M20: 0 | N20: ~ | O20: 442-0602 | P20: cafe.naver.com/cnctheater
A21: 20 | B21: 부산시 | C21: 중구 | D21: 롯데시네마 광복 | E21: 직영 | F21: 중구 중앙대로 2 마트/시네마동 9층 | G21: 11 | H21: 2409 | I21: 0 | J21: 11 | K21: 6 | L21: 0 | M21: 1 | N21: 샤롯데, 씨네커플, 수퍼플렉스, 수퍼4D, 씨네비즈 | O21: 1544-8855 | P21: www.lottecinema.co.kr | Q21: 41879
A22: 21 | B22: 부산시 | C22: 해운대구 | D22: CGV 센텀시티 | E22: 직영 | F22: 부산 해운대구 센텀남대로 35, 7층 (우동 1495번지 신세계센텀시티 7층) | G22: 10 | H22: 2093 | I22: 0 | J22: 10 | K22: 5 | L22: 0 | M22: 1 | N22: 4DX, STARIUM, Cine de Chef, 4DX, ScreenX, CGV 아트하우스 | O22: 1544-1122 | P22: www.cgv.co.kr | Q22: 39875
A23: 22 | B23: 부산시 | C23: 해운대구 | D23: 롯데시네마 센텀시티(백화점) | E23: 직영 | F23: 해운대구 센텀남대로 50 롯데백화점 8층 (우동 센텀시티 1496) | G23: 10 | H23: 1755 | I23: =G23-J23 -> 0 | J23: 10 | K23: 6 | L23: 0 | M23: 0 | N23: 1관 샤롯데, 8관 아르떼 | O23: 1544-8855 | P23: www.lottecinema.co.kr | Q23: 39423
A24: 23 | B24: 부산시 | C24: 해운대구 | D24: 롯데시네마 해운대 | E24: 위탁 | F24: 해운대구 해운대로 802, 7층 | G24: 10 | H24: 1688 | I24: 0 | J24: 10 | K24: 2 | L24: 0 | M24: 0 | N24: ~ | O24: 1544-8855 | P24: www.lottecinema.co.kr | Q24: 41639 | R24: (구)프리머스 해운대
A25: 24 | B25: 부산시 | C25: 해운대구 | D25: 메가박스 장산 | E25: 위탁 | F25: 해운대구 해운대로 813 NC백화점 8층 (좌동 1467-4) | G25: 7 | H25: 1019 | I25: 0 | J25: 7 | K25: 2 | L25: 0 | M25: 0 | N25: ~ | O25: 1544-0070 | P25: www.megabox.co.kr | Q25: 40910
A26: 25 | B26: 부산시 | C26: 해운대구 | D26: 메가박스 해운대 | E26: 직영 | F26: 해운대구 해운대로 648 스펀지몰 6층 (우1동 587-1) | G26: 10 | H26: 1794 | I26: 0 | J26: 10 | K26: 2 | L26: 0 | M26: 0 | N26: Table M관, M관 | O26: 1544-0070 | P26: www.megabox.co.kr | Q26: 37590
A27: 26 | B27: 부산시 | C27: 해운대구 | D27: 영화의 전당 | E27: ~ | F27: 해운대구 수영강변대로 120 (우1동 1467) | G27: 3 | H27: 837 | I27: 0 | J27: 3 | K27: 3 | L27: 0 | M27: 0 | N27: ~ | O27: 780-6050 | P27: www.dureraum.org | Q27: 40858 | R27: 4,5관은 공연장으로 등록. 통계제외함
A30: 2014년 휴폐관 극장
A31: 1 | B31: 부산시 | C31: 금정구 | D31: 메가박스 오투 | E31: 위탁 | F31: 금정구 부곡 2동 298번지 | G31: 7 | H31: 1177 | I31: =G31-J31 -> 0 | J31: 7 | K31: 2 | M31: 0 | N31: ~ | O31: 1544-0070 | P31: www.megabox.co.kr | Q31: 38961 | R31: 2014.12.22 영업종료 / 2015.1.1 롯데시네마 오투로 전환

Sheet 대구
A1: 번호 | B1: 광역단체 | C1: 기초단체 | D1: 영화관명 | E1: 대기업 운영 여부 | F1: 소재지 | G1: 총스크린수 | H1: 총좌석수 | I1: 필름 전용관수 | J1: 디지털 2D 상영관수 | K1: 3D 가능관수 | L1: IMAX 상영관 수 | M1: 4D 상영관수 | N1: 특별관 운영 여부 | O1: 전화번호(053) | P1: 홈페이지 | Q1: 개관일 | R1: 비고
A2: 1 | B2: 대구시 | C2: 달서구 | D2: 롯데시네마 성서 | E2: 직영 | F2: 달서구 성서로 414 (이곡동 1244-1) | G2: 9 | H2: 1617 | I2: =G2-J2 -> 0 | J2: 9 | K2: 6 | L2: 0 | M2: 0 | N2: ~ | O2: 1544-8855 | P2: www.lottecinema.co.kr | Q2: 39346
A3: 2 | B3: 대구시 | C3: 동구 | D3: CGV 대구이시아 | E3: 위탁 | F3: 동구 팔공로 49길 16, 3층 (봉무동 1545 롯데몰13층) | G3: 7 | H3: 974 | I3: =G3-J3 -> 0 | J3: 7 | K3: 3 | L3: 0 | M3: 0 | N3: ~ | O3: 1544-1122 | P3: www.cgv.co.kr | Q3: 40663
A4: 3 | B4: 대구시 | C4: 동구 | D4: 롯데시네마 대구율하 | E4: 직영 | F4: 동구 안심로 80 (율하동 1117) | G4: 6 | H4: 1386 | I4: =G4-J4 -> 0 | J4: 6 | K4: 4 | L4: 0 | M4: 0 | N4: ~ | O4: 1544-8855 | P4: www.lottecinema.co.kr | Q4: 40374
A5: 4 | B5: 대구시 | C5: 북구 | D5: CGV 대구칠곡 | E5: 위탁 | F5: 북구 동암로 90 (동천동 894-1번지 세븐밸리 5층) | G5: 7 | H5: 1171 | I5: 0 | J5: 7 | K5: 3 | L5: 0 | M5: 0 | N5: ~ | O5: 1544-1122 | P5: www.cgv.co.kr | Q5: 39386
A6: 5 | B6: 대구시 | C6: 북구 | D6: 롯데시네마 대구 | E6: 직영 | F6: 북구 태평로 161 (칠성동 2가 302-155) | G6: 9 | H6: 1627 | I6: =G6-J6 -> 0 | J6: 9 | K6: 5 | L6: 0 | M6: 0 | N6: 9관 아르떼 | O6: 1544-8855 | P6: www.lottecinema.co.kr | Q6: 37679
A7: 6 | B7: 대구시 | C7: 북구 | D7: 롯데시네마 프리미엄칠곡 | E7: 위탁 | F7: 북구 학정로 422 태을빌딩 5층 (구암동 769-1) | G7: 6 | H7: 536 | I7: 0 | J7: 6 | K7: 3 | L7: 0 | M7: 0 | N7: ~ | O7: 1544-8855 | P7: www.lottecinema.co.kr | Q7: 41517
A8: 7 | B8: 대구시 | C8: 북구 | D8: 메가박스 대구(칠성로) | E8: 직영 | F8: 북구 침산로 93 스펙트럼시티 4층 (칠성동 2가 20) | G8: 10 | H8: 1951 | I8: 0 | J8: 10 | K8: 3 | L8: 0 | M8: 0 | N8: Table M관,M관 | O8: 1544-0070 | P8: www.megabox.co.kr | Q8: 37372
A9: 8 | B9: 대구시 | C9: 북구 | D9: 메가박스 북대구(칠곡) | E9: 위탁 | F9: 북구 동암로 100 (동천동 895-2) | G9: 6 | H9: 886 | I9: =G9-J9 -> 0 | J9: 6 | K9: 1 | L9: 0 | M9: 0 | N9: ~ | O9: 1544-0070 | P9: www.megabox.co.kr | Q9: 39341
A10: 9 | B10: 대구시 | C10: 서구 | D10: 롯데시네마 대구광장 | E10: 직영 | F10: 서구 달구벌대로 1691 엠프라자 4층 (내당동) | G10: 7 | H10: 1300 | I10: 0 | J10: 7 | K10: 2 | L10: 0 | M10: 0 | N10: ~ | O10: 1544-8855 | P10: www.lottecinema.co.kr | Q10: 41180
A11: 10 | B11: 대구시 | C11: 수성구 | D11: 시네마M | E11: ~ | F11: 수성구 동대구로 400 대구문화방송 (범어2동) | G11: 1 | H11: 520 | I11: =G11-J11 -> 0 | J11: 1 | K11: 1 | L11: 0 | M11: 0 | N11: ~ | O11: 744-6114 | P11: www.cinemam.co.kr | Q11: 36861
A12: 11 | B12: 대구시 | C12: 수성구 | D12: CGV 대구수성 | E12: 직영 | F12: 수성구 지범로 191, 8층 (범물동 1273) | G12: 4 | H12: 804 | I12: 0 | J12: 4 | K12: 2 | L12: 0 | M12: 0 | N12: ~ | O12: 1544-1122 | P12: www.cgv.co.kr | Q12: 41417 | R12: (구)프리머스 수성
A13: 12 | B13: 대구시 | C13: 수성구 | D13: CGV 대구스타디움 | E13: 직영 | F13: 수성구 유니버시아드로 140 (대흥동 504번지) | G13: 10 | H13: 1466 | I13: =G13-J13 -> 0 | J13: 10 | K13: 6 | L13: 0 | M13: 0 | N13: ~ | O13: 1544-1122 | P13: www.cgv.co.kr | Q13: 40764
A14: 13 | B14: 대구시 | C14: 중구 | D14: CGV 대구 | E14: 직영 | F14: 중구 국채보상로 585, 5층~9층 (사일동 15-1) | G14: 12 | H14: 1625 | I14: =G14-J14 -> 0 | J14: 12 | K14: 5 | L14: 1 | M14: 1 | N14: 4DX, IMAX, sweetbox, CGV 아트하우스, ScreenX, Veatbox | O14: 1544-1122 | P14: www.cgv.co.kr | Q14: 39337
A15: 14 | B15: 대구시 | C15: 중구 | D15: CGV 대구아카데미 | E15: 직영 | F15: 중구 중앙대로 412 (남일동) | G15: 7 | H15: 1171 | I15: 0 | J15: 7 | K15: 2 | L15: 0 | M15: 0 | N15: ~ | O15: 1544-1122 | P15: www.cgv.co.kr | Q15: 41663 | R15: (구)롯데시네마 대구아카데미
A16: 15 | B16: 대구시 | C16: 중구 | D16: CGV 대구한일 | E16: 직영 | F16: 중구 동성로 39, 7층 (동성로 2가 88-2 씨네시티한일 7층) | G16: 5 | H16: 832 | I16: 0 | J16: 5 | K16: 2 | L16: 0 | M16: 0 | N16: Sweetbox | O16: 1544-1122 | P16: www.cgv.co.kr | Q16: 41271 | R16: (구)대구한일극장 ->(구)메가박스 대구한일
A17: 16 | B17: 대구시 | C17: 중구 | D17: CGV 대구현대 | E17: 직영 | F17: 중구 달구벌대로 2077, 지하2층 (계산동 2가 200번지 지하2층) | G17: 6 | H17: 710 | I17: =G17-J17 -> 0 | J17: 6 | K17: 3 | L17: 0 | M17: 0 | N17: Sweetbox, Veatbox | O17: 1544-1122 | P17: www.cgv.co.kr | Q17: 40774
A18: 17 | B18: 대구시 | C18: 중구 | D18: MMC만경관 | E18: ~ | F18: 중구 국채보상로 57 (동성로1가 29-4) | G18: 9 | H18: 859 | I18: 0 | J18: 9 | K18: 2 | L18: 0 | M18: 0 | N18: ~ | O18: 257-2041 | P18: www.mmc24.co.kr | Q18: 37435 | R18: 10관~15관 폐관
A19: 18 | B19: 대구시 | C19: 중구 | D19: 동성아트홀 | E19: ~ | F19: 중구 동성로 69 (동성로1가 22) | G19: 1 | H19: 201 | I19: 0 | J19: 1 | K19: 0 | L19: 0 | M19: 0 | N19: ~ | O19: 425-2845 | P19: café.naver.com/dartholic | Q19: 33878
A20: 19 | B20: 대구시 | C20: 중구 | D20: 롯데시네마 동성로 | E20: 직영 | F20: 중구 동성로 2길 95 | G20: 9 | H20: 1412 | I20: =G20-J20 -> 0 | J20: 9 | K20: 5 | L20: 0 | M20: 0 | N20: 1관 샤롯데 | O20: 1544-8855 | P20: www.lottecinema.co.kr | Q20: 39586
A21: 20 | B21: 대구시 | C21: 중구 | D21: 그레이스실버영화관 | E21: ~ | F21: 중구 경상감영길 137 | G21: 1 | H21: 139 | I21: 0 | J21: 1 | K21: 0 | L21: 0 | M21: 0 | N21: ~ | O21: 431-1571 | P21: blog.daum.net/ghdae | Q21: 41874
G22: =SUM(G2:G21) -> 132 | H22: =SUM(H2:H21) -> 21187 | I22: =SUM(I2:I21) -> 0 | J22: =SUM(J2:J21) -> 132

Sheet 인천
A1: 번호 | B1: 광역단체 | C1: 기초단체 | D1: 영화관명 | E1: 대기업 운영 여부 | F1: 소재지 | G1: 총스크린수 | H1: 총좌석수 | I1: 필름 전용관수 | J1: 디지털 2D 상영관수 | K1: 3D 가능관수 | L1: IMAX 상영관 수 | M1: 4D 상영관수 | N1: 특별관 운영 여부 | O1: 전화번호(032) | P1: 홈페이지 | Q1: 개관일 | R1: 비고
A2: 1 | B2: 인천시 | C2: 계양구 | D2: CGV 계양 | E2: 직영 | F2: 계양구 장제로 738, 8층 (작전동 899-1 8~11층) | G2: 8 | H2: 1219 | I2: =G2-J2 -> 0 | J2: 8 | K2: 4 | L2: 0 | M2: 0 | N2: Sweetbox, Veatbox | O2: 1544-1122 | P2: www.cgv.co.kr | Q2: 38985
A3: 2 | B3: 인천시 | C3: 남구 | D3: CGV 인천터미널 | E3: 직영 | F3: 남구 연남로 35, 지하1층 (관교동 15 신세계백화점 지하1층) | G3: 4 | H3: 516 | I3: 0 | J3: 4 | K3: 2 | L3: 0 | M3: 0 | N3: Sweetbox | O3: 1544-1122 | P3: www.cgv.co.kr | Q3: 38604 | R3: (구)CGV 관교
A4: 3 | B4: 인천시 | C4: 남구 | D4: CGV 주안 | E4: 직영 | F4: 남구 염창로 58, 6층 (주안동 30-1 카라아울렛 6~10층) | G4: 9 | H4: 1690 | I4: =G4-J4 -> 0 | J4: 9 | K4: 4 | L4: 0 | M4: 0 | N4: Sweetbox | O4: 1544-1122 | P4: www.cgv.co.kr | Q4: 38414
A5: 4 | B5: 인천시 | C5: 남구 | D5: 영화공간 주안 | E5: ~ | F5: 남구 미추홀대로 716 메인프라자7층 (주안1동 166-1) | G5: 3 | H5: 346 | I5: 0 | J5: 3 | K5: 0 | L5: 0 | M5: 0 | N5: ~ | O5: 427-6777 | P5: www.cinespacejuan.com | Q5: 39203 | R5: 구 프리머스 주안/ 1,3관은 DLP프로젝터 상영
A6: 5 | B6: 인천시 | C6: 남구 | D6: CGV 남주안 | E6: 위탁 | F6: 남구 미추홀대로 736 (주안동 9층 18호) | G6: 7 | H6: 921 | I6: 0 | J6: 7 | K6: 0 | L6: 0 | M6: 0 | N6: ~ | O6: 1544-1122 | P6: www.cgv.co.kr | Q6: 41887
A7: 6 | B7: 인천시 | C7: 남동구 | D7: CGV 인천 | E7: 직영 | F7: 남동구 예술로 198, 4층 (구월동 1130 씨엔씨빌딩 4층) | G7: 14 | H7: 3390 | I7: =G7-J7 -> 0 | J7: 14 | K7: 5 | L7: 1 | M7: 1 | N7: IMAX, ScreenX, Sweetbox, CGV 아트하우스, 4DX, Veatbox | O7: 1544-1122 | P7: www.cgv.co.kr | Q7: 36512
A8: 7 | B8: 인천시 | C8: 남동구 | D8: CGV 인천논현 | E8: 직영 | F8: 남동구 논현로 26번길34, 4층 (논현동 646-2 시네마타워4층) | G8: 5 | H8: 630 | I8: =G8-J8 -> 0 | J8: 5 | K8: 2 | L8: 0 | M8: 0 | N8: ~ | O8: 1544-1122 | P8: www.cgv.co.kr | Q8: 40438
A9: 8 | B9: 인천시 | C9: 남동구 | D9: 롯데시네마 인천 | E9: 직영 | F9: 남동구 예술로 148 롯데백화점 7층 (구월동 1455) | G9: 9 | H9: 1341 | I9: =G9-J9 -> 0 | J9: 9 | K9: 7 | L9: 0 | M9: 0 | N9: 1관 샤롯데 | O9: 1544-8855 | P9: www.lottecinema.co.kr | Q9: 39954
A10: 9 | B10: 인천시 | C10: 동구 | D10: 추억극장 미림 | E10: ~ | F10: 동구 화도진로 31 (송현동 92-7) | G10: 1 | H10: 283 | I10: 0 | J10: 1 | K10: 0 | L10: 0 | M10: 0 | N10: ~ | O10: 032-764-6920 | Q10: 41549 | R10: DV CAM 상영
A11: 10 | B11: 인천시 | C11: 부평구 | D11: CGV 부평 | E11: 위탁 | F11: 부평구 마장로 489 (청천동 386) | G11: 10 | H11: 1464 | I11: =G11-J11 -> 0 | J11: 10 | K11: 0 | L11: 0 | M11: 0 | N11: Sweetbox | O11: 1544-1122 | P11: www.cgv.co.kr | Q11: 38157
A12: 11 | B12: 인천시 | C12: 부평구 | D12: 대한극장 | E12: ~ | F12: 부평구 경원대로 1382 (부평1동 201-9) | G12: 2 | H12: 240 | I12: 0 | J12: 2 | K12: 1 | L12: 0 | M12: 0 | N12: ~ | O12: 503-3330 | P12: dht.movieplus.or.kr | Q12: 1973-07-01
A13: 12 | B13: 인천시 | C13: 부평구 | D13: 롯데시네마 부평 | E13: 직영 | F13: 부평구 대정로 66 (부평동 152-1) | G13: 9 | H13: 1523 | I13: =G13-J13 -> 0 | J13: 9 | K13: 4 | L13: 0 | M13: 0 | N13: 9관 아르떼 | O13: 1544-8855 | P13: www.lottecinema.co.kr | Q13: 38777
A14: 13 | B14: 인천시 | C14: 부평구 | D14: 롯데시네마 부평역사 | E14: 직영 | F14: 부평구 광장로 16 (부평동 738-21) | G14: 9 | H14: 1218 | I14: =G14-J14 -> 0 | J14: 9 | K14: 4 | L14: 0 | M14: 0 | N14: ~ | O14: 1544-8855 | P14: www.lottecinema.co.kr | Q14: 39695
A15: 14 | B15: 인천시 | C15: 부평구 | D15: CGV 부평역 | E15: 위탁 | F15: 부평구 경원대로 1395 | G15: 6 | H15: 730 | I15: 0 | J15: 6 | K15: 0 | L15: 0 | M15: 0 | N15: ~ | O15: 1544-1122 | P15: www.cgv.co.kr | Q15: 41842
A16: 15 | B16: 인천시 | C16: 서구 | D16: 롯데시네마 검단 | E16: 직영 | F16: 서구 완정로 163 (마천동 698-7) | G16: 6 | H16: 624 | I16: =G16-J16 -> 0 | J16: 6 | K16: 2 | L16: 0 | M16: 0 | N16: ~ | O16: 1544-8855 | P16: www.lottecinema.co.kr | Q16: 38988
A17: 16 | B17: 인천시 | C17: 연수구 | D17: CGV 인천연수 | E17: 위탁 | F17: 연수구 청능대로 210, 4층 (동춘동 926 스퀘어원쇼핑몰 4층) | G17: 6 | H17: 1127 | I17: 0 | J17: 6 | K17: 2 | L17: 0 | M17: 0 | N17: ~ | O17: 1544-1122 | P17: www.cgv.co.kr | Q17: 41187
A18: 17 | B18: 인천시 | C18: 연수구 | D18: 메가박스 연수 | E18: 직영 | F18: 연수구 벚꽃로 106 광장프라자 (청학동 496-4) | G18: 9 | H18: 1498 | I18: =G18-J18 -> 0 | J18: 9 | K18: 3 | L18: 0 | M18: 0 | N18: ~ | O18: 1544-0070 | P18: www.megabox.co.kr | Q18: 38533
A19: 18 | B19: 인천시 | C19: 중구 | D19: CGV 인천공항 | E19: 직영 | F19: 중구 공항로 272, 지하1층 (운서동 2850) | G19: 2 | H19: 245 | I19: 0 | J19: 2 | K19: 2 | L19: 0 | M19: 0 | N19: ~ | O19: 1544-1122 | P19: www.cgv.co.kr | Q19: 40924
A20: 19 | B20: 인천시 | C20: 중구 | D20: 애관극장 | E20: ~ | F20: 중구 개항로 63-2 (경동 238번지) | G20: 5 | H20: 809 | I20: 0 | J20: 5 | K20: 0 | L20: 0 | M20: 0 | N20: ~ | O20: 761-5951 | P20: www.aekwan.co.kr | Q20: 38002

Sheet 광주
A1: 번호 | B1: 광역단체 | C1: 기초단체 | D1: 영화관명 | E1: 대기업 운영 여부 | F1: 소재지 | G1: 총스크린수 | H1: 총좌석수 | I1: 필름 전용관수 | J1: 디지털 2D 상영관수 | K1: 3D 가능관수 | L1: IMAX 상영관 수 | M1: 4D 상영관수 | N1: 특별관 운영 여부 | O1: 전화번호(062) | P1: 홈페이지 | Q1: 개관일 | R1: 비고
A2: 1 | B2: 광주시 | C2: 광산구 | D2: CGV 광주첨단 | E2: 위탁 | F2: 광산구 임방울대로 826번길, 2층 (쌍암동 667-9) | G2: 9 | H2: 1534 | I2: =G2-J2 -> 0 | J2: 9 | K2: 4 | L2: 0 | M2: 0 | N2: Sweetbox | O2: 1544-1122 | P2: www.cgv.co.kr | Q2: 38729
A3: 2 | B3: 광주시 | C3: 광산구 | D3: 롯데시네마 수완 | E3: 직영 | F3: 광산구 장신로 98 롯데아울렛 (장신동) | G3: 7 | H3: 1397 | I3: 0 | J3: 7 | K3: 5 | L3: 0 | M3: 1 | N3: 수퍼4D, 수퍼사운드 | O3: 1544-8855 | P3: www.lottecinema.co.kr | Q3: 40963
A4: 3 | B4: 광주시 | C4: 광산구 | D4: 메가박스 첨단 | E4: 위탁 | F4: 광산구 앰코로 35 (쌍암동 688-4) | G4: 9 | H4: 1159 | I4: 0 | J4: 9 | K4: 2 | L4: 0 | M4: 0 | N4: ~ | O4: 1544-0070 | P4: www.megabox.co.kr | Q4: 40923
A5: 4 | B5: 광주시 | C5: 광산구 | D5: 메가박스 콜롬버스 하남 | E5: 위탁 | F5: 광산구 풍영철길로 15 (우산동1587-1) | G5: 10 | H5: 1609 | I5: =G5-J5 -> 0 | J5: 10 | K5: 3 | L5: 0 | M5: 0 | N5: ~ | O5: 1544-0070 | P5: www.megabox.co.kr | Q5: 38596
A6: 5 | B6: 광주시 | C6: 동구 | D6: 광주극장 | E6: ~ | F6: 동구 충장로 46번길 10 (충장로 5가 62) | G6: 1 | H6: 850 | I6: =G6-J6 -> 0 | J6: 1 | K6: 0 | L6: 0 | M6: 0 | N6: ~ | O6: 224-5858 | P6: cafe.naver.com/cinemagwangju/ | Q6: 1933-00-00
A7: 6 | B7: 광주시 | C7: 동구 | D7: 광주영상복합문화관 G시네마 | E7: ~ | F7: 동구 제봉로 96 (서석동 47번지 1호) | G7: 1 | H7: 105 | I7: =G7-J7 -> 0 | J7: 1 | K7: 1 | L7: 0 | M7: 0 | N7: ~ | O7: 350-0341 | P7: cafe.naver.com/gcinema | Q7: 40234
A8: 7 | B8: 광주시 | C8: 동구 | D8: 롯데시네마 광주(롯데백화점) | E8: 직영 | F8: 동구 독립로 268 롯데백화점 9층 (대인동 7-1) | G8: 6 | H8: 1024 | I8: =G8-J8 -> 0 | J8: 6 | K8: 3 | L8: 0 | M8: 0 | N8: 1관 샤롯데 | O8: 1544-8855 | P8: www.lottecinema.co.kr | Q8: 2000-07-00
A9: 8 | B9: 광주시 | C9: 동구 | D9: 메가박스 광주(충장로) | E9: 직영 | F9: 동구 중앙로 160번길 16-7 (불로동 1-21) | G9: 9 | H9: 1506 | I9: =G9-J9 -> 0 | J9: 9 | K9: 1 | L9: 0 | M9: 0 | N9: 1관 Table M관, M관 | O9: 1544-0070 | P9: www.megabox.co.kr | Q9: 38743 | R9: (구)씨네씨티
A10: 9 | B10: 광주시 | C10: 동구 | D10: 롯데시네마 충장로 | E10: 위탁 | F10: 동구 충장로안길 12 (황금동 12-2) | G10: 9 | H10: 1101 | I10: 0 | J10: 9 | K10: 2 | L10: 0 | M10: 0 | N10: 씨네커플 | O10: 1544-8855 | P10: www.lottecinema.co.kr | Q10: 41627
A11: 10 | B11: 광주시 | C11: 북구 | D11: 메가박스 전대(광주) | E11: 위탁 | F11: 북구 우치로 60 (중흥동 362-3) | G11: 7 | H11: 1185 | I11: =G11-J11 -> 0 | J11: 7 | K11: 2 | L11: 0 | M11: 0 | N11: ~ | O11: 1544-0070 | P11: www.megabox.co.kr | Q11: 39051
A12: 11 | B12: 광주시 | C12: 북구 | D12: CGV 광주용봉 | E12: 위탁 | F12: 북구 문화소통로 170 (용봉동 17-1 굿모닝타운 4층) | G12: 10 | H12: 1574 | I12: 0 | J12: 10 | K12: 0 | L12: 0 | M12: 0 | N12: ~ | O12: 1544-1122 | P12: www.cgv.co.kr | Q12: 41529
A13: 12 | B13: 광주시 | C13: 서구 | D13: CGV 광주상무 | E13: 직영 | F13: 서구 시청로 67 (프리미엄아울렛) 6층 | G13: 10 | H13: 1610 | I13: 0 | J13: 10 | K13: 0 | L13: 0 | M13: 0 | N13: ~ | O13: 1544-1122 | P13: www.cgv.co.kr | Q13: 2014-06-05 | R13: (구)롯데시네마 상무
A14: 13 | B14: 광주시 | C14: 서구 | D14: CGV 광주터미널 | E14: 직영 | F14: 서구 무진대로 904, 2층~6층 (광천동 49-1 유스퀘어 2~6층) | G14: 9 | H14: 1845 | I14: =G14-J14 -> 0 | J14: 9 | K14: 5 | L14: 1 | M14: 1 | N14: IMAX, 4DX, Sweetbox, Veatbox, ScreenX, CGV 아트하우스 | O14: 1544-1122 | P14: www.cgv.co.kr | Q14: 39954
A15: 14 | B15: 광주시 | C15: 서구 | D15: 메가박스 콜롬버스 상무 | E15: 위탁 | F15: 서구 시청로 60번길 21-6 (치평동 1223-3) | G15: 10 | H15: 1646 | I15: =G15-J15 -> 0 | J15: 10 | K15: 4 | L15: 0 | M15: 0 | N15: ~ | O15: 1544-0070 | P15: www.megabox.co.kr | Q15: 40330

Sheet 대전
A1: 번호 | B1: 광역단체 | C1: 기초단체 | D1: 영화관명 | E1: 대기업 운영 여부 | F1: 소재지 | G1: 총스크린수 | H1: 총좌석수 | I1: 필름 전용관수 | J1: 디지털 2D 상영관수 | K1: 3D 가능관수 | L1: IMAX 상영관 수 | M1: 4D 상영관수 | N1: 특별관 운영 여부 | O1: 전화번호(042) | P1: 홈페이지 | Q1: 개관일 | R1: 비고
A2: 1 | B2: 대전시 | C2: 동구 | D2: CGV 대전터미널 | E2: 직영 | F2: 동구 동서대로 1689, 3층 (용전동 63-3, 68-2) | G2: 7 | H2: 1409 | I2: =G2-J2 -> 0 | J2: 7 | K2: 4 | L2: 0 | M2: 0 | N2: ScreenX, Sweetbox, Veatbox | O2: 1544-1122 | P2: www.cgv.co.kr | Q2: 40899
A3: 2 | B3: 대전시 | C3: 동구 | D3: MCV아카데미 | E3: ~ | F3: 동구 대전로 813번길 9 (정동 26-10) | G3: 6 | H3: 1355 | I3: 0 | J3: 6 | K3: 0 | L3: 0 | M3: 0 | N3: ~ | O3: 1588-5362 | P3: www.mcv.co.kr | Q3: 38608 | R3: 5,6,7관 휴관
A4: 3 | B4: 대전시 | C4: 동구 | D4: 대전아트시네마 | E4: ~ | F4: 동구 중앙로 192, 3층 (중동 27-11) | G4: 1 | H4: 150 | I4: =G4-J4 -> 0 | J4: 1 | K4: 0 | L4: 0 | M4: 0 | N4: ~ | O4: 472-1138 | P4: www.cinei.org | Q4: 38808
A5: 4 | B5: 대전시 | C5: 동구 | D5: CGV 대전가오 | E5: 직영 | F5: 동구 은어송로 72, 4층 (가오동 72 홈플러스 4층) | G5: 7 | H5: 1052 | I5: 0 | J5: 7 | K5: 3 | L5: 0 | M5: 0 | N5: ~ | O5: 1544-1122 | P5: www.cgv.co.kr | Q5: 41340 | R5: (구)롯데시네마 대전가오
A6: 5 | B6: 대전시 | C6: 서구 | D6: 롯데시네마 대전 | E6: 직영 | F6: 서구 계룡로 598 롯데백화점 10층 (괴정동 423-1) | G6: 8 | H6: 1030 | I6: =G6-J6 -> 0 | J6: 8 | K6: 4 | L6: 0 | M6: 0 | N6: ~ | O6: 1544-8855 | P6: www.lottecinema.co.kr | Q6: 2000-05-05
A7: 6 | B7: 대전시 | C7: 서구 | D7: 메가박스 대전 | E7: 직영 | F7: 서구 문정로 77 로데오타운 5층 (탄방동 746) | G7: 8 | H7: 1388 | I7: =G7-J7 -> 0 | J7: 8 | K7: 4 | L7: 0 | M7: 0 | N7: ~ | O7: 1544-0070 | P7: www.megabox.co.kr | Q7: 38306
A8: 7 | B8: 대전시 | C8: 서구 | D8: 롯데시네마 대전둔산 | E8: 직영 | F8: 서구 대덕대로 325 스타게이트 12층 (월평동) | G8: 10 | H8: 1600 | I8: 0 | J8: 10 | K8: 3 | L8: 0 | M8: 0 | N8: ~ | O8: 1544-8855 | P8: www.lottecinema.co.kr | Q8: 41790 | R8: (구)CGV 대전둔산
A9: 8 | B9: 대전시 | C9: 유성구 | D9: CGV 유성노은 | E9: 위탁 | F9: 유성구 노은로 144 노은타운 7층 | G9: 5 | H9: 968 | I9: 0 | J9: 5 | K9: 0 | L9: 0 | M9: 0 | N9: ~ | O9: 1544-1122 | P9: www.cgv.co.kr | Q9: 41948 | R9: (구)씨네위
A10: 9 | B10: 대전시 | C10: 중구 | D10: CGV 대전 | E10: 직영 | F10: 중구 계백로 1700, 6층 (문화동 1-16 세이백화점 6층) | G10: 9 | H10: 1830 | I10: =G10-J10 -> 0 | J10: 9 | K10: 6 | L10: 1 | M10: 1 | N10: 4DX, IMAX, sweetbox, CGV 아트하우스, ScreenX, Veatbox | O10: 1544-1122 | P10: www.cgv.co.kr | Q10: 37121
A13: 2014년 휴폐관 극장
A14: 1 | B14: 대전시 | C14: 유성구 | D14: 씨네위 | E14: ~ | F14: 유성구 지족동 905-4 노은타운 | G14: 5 | H14: 968 | I14: 0 | J14: 5 | K14: 2 | M14: 0 | N14: ~ | O14: 476-1001 | P14: www.cinewe.co.kr | Q14: 38072 | R14: 2014.11.5 CGV 유성노은으로 재개관

Sheet 울산
A1: 번호 | B1: 광역단체 | C1: 기초단체 | D1: 영화관명 | E1: 대기업 운영 여부 | F1: 소재지 | G1: 총스크린수 | H1: 총좌석수 | I1: 필름 전용관수 | J1: 디지털 2D 상영관수 | K1: 3D 가능관수 | L1: IMAX 상영관 수 | M1: 4D 상영관수 | N1: 특별관 운영 여부 | O1: 전화번호(052) | P1: 홈페이지 | Q1: 개관일 | R1: 비고
A2: 1 | B2: 울산시 | C2: 남구 | D2: 롯데시네마 울산 | E2: 직영 | F2: 남구 삼산로 288 (삼산동 1480-1) | G2: 9 | H2: 1369 | I2: =G2-J2 -> 0 | J2: 9 | K2: 6 | L2: 0 | M2: 1 | N2: 수퍼4D, 수퍼바이브, 수퍼사운드 | O2: 1544-8855 | P2: www.lottecinema.co.kr | Q2: 37127
A3: 2 | B3: 울산시 | C3: 남구 | D3: CGV 울산삼산 | E3: 직영 | F3: 남구 화합로 185, 5층 (삼산동 1569-1 업스퀘어 5층) | G3: 11 | H3: 2341 | I3: 0 | J3: 11 | K3: 6 | L3: 1 | M3: 1 | N3: 4DX, IMAX, Sweetbox, Gold Class, ScreenX, Veatbox | O3: 1544-1122 | P3: www.cgv.co.kr | Q3: 41395
A4: 3 | B4: 울산시 | C4: 중구 | D4: 메가박스 울산 | E4: 직영 | F4: 중구 젊음의 거리 73 (성남동 251-8) | G4: 8 | H4: 1066 | I4: =G4-J4 -> 0 | J4: 8 | K4: 3 | L4: 0 | M4: 0 | N4: ~ | O4: 1544-0070 | P4: www.megabox.co.kr | Q4: 38344
A5: 4 | B5: 울산시 | C5: 중구 | D5: 롯데시네마 울산성남 | E5: 직영 | F5: 중구 젊음의 2거리 33 리버플레이스 10층 (성남동) | G5: 7 | H5: 1039 | I5: 0 | J5: 7 | K5: 2 | L5: 0 | M5: 0 | N5: ~ | O5: 1544-8855 | P5: www.lottecinema.co.kr | Q5: 41718 | R5: (구)CGV 울산
A6: 5 | B6: 울산시 | C6: 동구 | D6: 현대예술관 | E6: ~ | F6: 동구 명덕로 10 (서부동 110-1) | G6: 2 | H6: 207 | I6: 0 | J6: 2 | K6: 0 | L6: 0 | M6: 0 | N6: ~ | O6: 235-2100 | P6: www.hyundai-artscenter.co.kr | Q6: 2008-06-13 | R6: 영화관 2개관

Sheet 경기
A1: 번호 | B1: 광역단체 | C1: 기초단체 | D1: 영화관명 | E1: 대기업 운영 여부 | F1: 소재지 | G1: 총스크린수 | H1: 총좌석수 | I1: 필름 전용관수 | J1: 디지털 2D 상영관수 | K1: 3D 가능관수 | L1: IMAX 상영관 수 | M1: 4D 상영관수 | N1: 특별관 운영 여부 | O1: 전화번호 (031) | P1: 홈페이지 | Q1: 개관일 | R1: 비고
A2: 1 | B2: 경기도 | C2: 고양시 | D2: CGV 일산 | E2: 직영 | F2: 고양시 일산동구 정발산로 24 (장항동 867번지 웨스턴돔 3층) | G2: 9 | H2: 1794 | I2: =G2-J2 -> 0 | J2: 9 | K2: 5 | L2: 1 | M2: 1 | N2: 4DX, IMAX, Sweetbox, ScreenX, Veatbox | O2: 1544-1122 | P2: www.cgv.co.kr | Q2: 39170
A3: 2 | B3: 경기도 | C3: 고양시 | D3: CGV 화정 | E3: 위탁 | F3: 고양시 덕양구 화중로 104번길 28, 3층 (화정동 966-1 시네마플러스 401호) | G3: 8 | H3: 886 | I3: 0 | J3: 8 | K3: 3 | L3: 0 | M3: 0 | N3: ~ | O3: 1544-1122 | P3: www.cgv.co.kr | Q3: 41164
A4: 3 | B4: 경기도 | C4: 고양시 | D4: 롯데시네마 라페스타(일산) | E4: 직영 | F4: 고양시 일산동구 무궁화로 32-34, 3층 (장항동 764, 765 라페스타 C,D동 3층) | G4: 8 | H4: 1499 | I4: =G4-J4 -> 0 | J4: 8 | K4: 5 | L4: 0 | M4: 0 | N4: ~ | O4: 1544-8855 | P4: www.lottecinema.co.kr | Q4: 37819
A5: 4 | B5: 경기도 | C5: 고양시 | D5: 롯데시네마 주엽(일산) | E5: 직영 | F5: 고양시 일산서구 중앙로 1436 그랜드백화점 9층 (주엽2동) | G5: 9 | H5: 1241 | I5: =G5-J5 -> 0 | J5: 9 | K5: 2 | L5: 0 | M5: 0 | N5: 아르떼 | O5: 1544-8855 | P5: www.lottecinema.co.kr | Q5: 40847
A6: 5 | B6: 경기도 | C6: 고양시 | D6: 메가박스 백석 | E6: 직영 | F6: 고양시 일산동구 중앙로 1036 고양종합터미널 5층 | G6: 7 | H6: 1224 | I6: 0 | J6: 7 | K6: 3 | L6: 0 | M6: 0 | N6: Table M관, M관 | O6: 1544-0070 | P6: www.megabox.co.kr | Q6: 41243
A7: 6 | B7: 경기도 | C7: 고양시 | D7: 메가박스 일산 | E7: 위탁 | F7: 고양시 일산서구 덕이로 20 (덕이동 219-8) | G7: 8 | H7: 1101 | I7: =G7-J7 -> 0 | J7: 8 | K7: 2 | L7: 0 | M7: 0 | N7: ~ | O7: 1544-0070 | P7: www.megabox.co.kr | Q7: 39274
A8: 7 | B8: 경기도 | C8: 고양시 | D8: 메가박스 킨텍스 | E8: 직영 | F8: 고양시 일산서구 호수로 817 레이킨스몰 3층 (대화동) | G8: 8 | H8: 1600 | I8: =G8-J8 -> 0 | J8: 8 | K8: 0 | L8: 0 | M8: 0 | N8: Table M관, M관, The First Club | O8: 1544-0070 | P8: www.megabox.co.kr | Q8: 40430
A9: 8 | B9: 경기도 | C9: 광명시 | D9: CGV 광명철산 | E9: 위탁 | F9: 광명시 철산로 30번길 14 (철산동 436 덕수빌딩 4층) | G9: 6 | H9: 476 | I9: 0 | J9: 6 | K9: 0 | L9: 0 | M9: 0 | N9: ~ | O9: 1544-1122 | P9: www.cgv.co.kr | Q9: 41663 | R9: (구)프리머스 광명
A10: 9 | B10: 경기도 | C10: 광명시 | D10: 롯데시네마 광명아울렛 | E10: 직영 | F10: 광명시 일직로 17 롯데프리미엄아울렛 광명점 5층 | G10: 7 | H10: 1218 | I10: 0 | J10: 7 | K10: 2 | L10: 0 | M10: 0 | N10: 수퍼플렉스 | O10: 1544-8855 | P10: www.lottecinema.co.kr | Q10: 41978
A11: 10 | B11: 경기도 | C11: 광주시 | D11: 롯데시네마 광주터미널 | E11: 직영 | F11: 광주시 광주대로 30 2층 (경안동 25-3 광주버스터미널 2층) | G11: 3 | H11: 215 | I11: 0 | J11: 3 | K11: 2 | L11: 0 | M11: 0 | N11: ~ | O11: 1544-8855 | P11: www.lottecinema.co.kr | Q11: 41117
A12: 11 | B12: 경기도 | C12: 구리시 | D12: 롯데시네마 구리 | E12: 직영 | F12: 구리시 경춘로 243 (인창동 676-2) | G12: 7 | H12: 1303 | I12: =G12-J12 -> 0 | J12: 7 | K12: 5 | L12: 0 | M12: 0 | N12: ~ | O12: 1544-8855 | P12: www.lottecinema.co.kr | Q12: 38890
A13: 12 | B13: 경기도 | C13: 구리시 | D13: 롯데시네마 구리아울렛 | E13: 직영 | F13: 구리시 동구릉로 136번길 47 | G13: 7 | H13: 1052 | I13: 0 | J13: 7 | K13: 2 | L13: 0 | M13: 0 | N13: ~ | O13: 1544-8855 | P13: www.lottecinema.co.kr | Q13: 41997
A14: 13 | B14: 경기도 | C14: 군포시 | D14: 롯데시네마 산본 | E14: 위탁 | F14: 군포시 번영로 505 (산본동 1142-2,3 대우디오플러스 4층) | G14: 6 | H14: 704 | I14: =G14-J14 -> 0 | J14: 6 | K14: 2 | L14: 0 | M14: 0 | N14: ~ | O14: 1544-8855 | P14: www.lottecinema.co.kr | Q14: 39037 | R14: (구)CNI시네마
A15: 14 | B15: 경기도 | C15: 김포시 | D15: CGV 김포 | E15: 위탁 | F15: 김포시 사우동 928 | G15: 5 | H15: 500 | I15: 0 | J15: 5 | K15: 0 | L15: 0 | M15: 0 | N15: ~ | O15: 1544-1122 | P15: www.cgv.co.kr | Q15: 37570 | R15: (구)프리머스 김포
A16: 15 | B16: 경기도 | C16: 김포시 | D16: CGV 김포운양 | E16: 직영 | F16: 김포시 김포한강 11로 288-31 에이스프라자 7층 | G16: 4 | H16: 424 | I16: 0 | J16: 4 | K16: 2 | L16: 0 | M16: 0 | N16: ~ | O16: 1544-1122 | P16: www.cgv.co.kr | Q16: 41943
A17: 16 | B17: 경기도 | C17: 김포시 | D17: CGV 김포풍무 | E17: 직영 | F17: 김포시 풍무로 167, 지하1층 (풍무동 38-1 홈플러스 지하1층) | G17: 2 | H17: 192 | I17: =G17-J17 -> 0 | J17: 2 | K17: 1 | L17: 0 | M17: 0 | N17: ~ | O17: 1544-1122 | P17: www.cgv.co.kr | Q17: 40794
A18: 17 | B18: 경기도 | C18: 김포시 | D18: 메가박스 김포 | E18: 위탁 | F18: 김포시 걸포로 6 (걸포동 미도프라자 7~8층) | G18: 4 | H18: 479 | I18: 0 | J18: 4 | K18: 1 | L18: 0 | M18: 0 | N18: Table M관 | O18: 1544-0070 | P18: www.megabox.co.kr | Q18: 41695
A19: 18 | B19: 경기도 | C19: 남양주시 | D19: 롯데시네마 진접 | E19: 직영 | F19: 남양주시 진접읍 해밀예당1로 36 래일스타 9층 (금곡리 1081-2) | G19: 3 | H19: 320 | I19: =G19-J19 -> 0 | J19: 3 | K19: 2 | L19: 0 | M19: 0 | N19: ~ | O19: 1544-8855 | P19: www.lottecinema.co.kr | Q19: 40534
A20: 19 | B20: 경기도 | C20: 남양주시 | D20: 메가박스 남양주 | E20: 위탁 | F20: 남양주시 늘을2로 26 메인씨네마타워 8,9층 (호평동 640) | G20: 8 | H20: 1149 | I20: 0 | J20: 8 | K20: 3 | L20: 0 | M20: 0 | N20: ~ | O20: 1544-0070 | P20: www.megabox.co.kr | Q20: 40617
A21: 20 | B21: 경기도 | C21: 남양주시 | D21: 메가박스 별내 | E21: 위탁 | F21: 남양주시 두물로 19 (별내동 황산빌딩) | G21: 3 | H21: 331 | I21: 0 | J21: 3 | K21: 2 | L21: 0 | M21: 0 | N21: ~ | O21: 1544-0070 | P21: www.megabox.co.kr | Q21: 41996
A22: 21 | B22: 경기도 | C22: 남양주시 | D22: 롯데시네마 마석 | E22: 직영 | F22: 남양주시 화도읍 경춘로 1992 (마석우리 255-24) | G22: 2 | H22: 172 | I22: 0 | J22: 2 | K22: 2 | L22: 0 | M22: 0 | N22: ~ | O22: 1544-8855 | P22: www.lottecinema.co.kr | Q22: 41452
A23: 22 | B23: 경기도 | C23: 동두천시 | D23: 동광극장 | E23: ~ | F23: 동두천시 동광로 33 (중앙동 828) | G23: 1 | H23: 283 | I23: 0 | J23: 1 | K23: 0 | L23: 0 | M23: 0 | N23: ~ | O23: 867-3030 | P23: dgt.movieplus.or.kr/ | Q23: 31594 | R23: (구)동광극장
A24: 23 | B24: 경기도 | C24: 동두천시 | D24: 문화극장 | E24: ~ | F24: 동두천시 동광로 66 (생연3동 616) | G24: 2 | H24: 293 | I24: 0 | J24: 2 | K24: 1 | L24: 0 | M24: 0 | N24: ~ | O24: 863-3000 | P24: mht.movieplus.or.kr/ | Q24: 26299
A25: 24 | B25: 경기도 | C25: 부천시 | D25: CGV 부천 | E25: 직영 | F25: 부천시 원미구 길주로 180, 5층 (중동 1164 로담코 플라자 5~7층) | G25: 8 | H25: 1450 | I25: =G25-J25 -> 0 | J25: 8 | K25: 4 | L25: 0 | M25: 1 | N25: 4DX, Sweetbox, ScreenX, Veatbox | O25: 1544-1122 | P25: www.cgv.co.kr | Q25: 37855
A26: 25 | B26: 경기도 | C26: 부천시 | D26: CGV 소풍 | E26: 직영 | F26: 부천시 원미구 송내대로 239, 6층 (상동 539-1 소풍 6,7층) | G26: 11 | H26: 1725 | I26: 0 | J26: 11 | K26: 3 | L26: 1 | M26: 0 | N26: IMAX, CGV 아트하우스 | O26: 1544-1122 | P26: www.cgv.co.kr | Q26: 39337 | R26: (구)프리머스 소풍
A27: 26 | B27: 경기도 | C27: 부천시 | D27: CGV 역곡 | E27: 직영 | F27: 부천시 소사구 경인로 505, 6층 (괴안동 역곡하이뷰 6층) | G27: 6 | H27: 776 | I27: =G27-J27 -> 0 | J27: 6 | K27: 3 | L27: 0 | M27: 0 | N27: ~ | O27: 1544-1122 | P27: www.cgv.co.kr | Q27: 38714
A28: 27 | B28: 경기도 | C28: 부천시 | D28: 롯데시네마 부천(신중동역) | E28: 직영 | F28: 원미구 길주로 289 (중동 1141-2) | G28: 8 | H28: 1347 | I28: =G28-J28 -> 0 | J28: 8 | K28: 3 | L28: 0 | M28: 0 | N28: ~ | O28: 1544-8855 | P28: www.lottecinema.co.kr | Q28: 40619
A29: 28 | B29: 경기도 | C29: 부천시 | D29: 롯데시네마 부천역 | E29: 위탁 | F29: 원미구 부천로 11 (심곡동) | G29: 9 | H29: 789 | I29: 0 | J29: 9 | K29: 2 | L29: 0 | M29: 0 | N29: ~ | O29: 1544-8855 | P29: www.lottecinema.co.kr | Q29: 41312 | R29: (구)더잼
A30: 29 | B30: 경기도 | C30: 부천시 | D30: 한국만화영상진흥원 | E30: ~ | F30: 부천시 원미구 길주로 1 (상3동 529-2) | G30: 1 | H30: 386 | I30: 0 | J30: 1 | K30: 1 | L30: 0 | M30: 0 | N30: ~ | O30: 310-3093 | P30: www.comicsmuseum.org | Q30: 40038
A31: 30 | B31: 경기도 | C31: 부천시 | D31: CGV 부천역 | E31: 직영 | F31: 부천시 원미구 부일로 460 | G31: 8 | H31: 1271 | I31: 0 | J31: 8 | K31: 1 | L31: 0 | M31: 0 | N31: ~ | O31: 1544-1122 | P31: www.cgv.co.kr | Q31: 41795 | R31: (구)MMC부천 ->(구)메가박스 부천MMC
A32: 31 | B32: 경기도 | C32: 성남시 | D32: CGV 야탑 | E32: 직영 | F32: 성남시 분당구 성남대로 925번길 16, 지하2층 (야탑동 341 테마폴리스빌딩 지하2층) | G32: 8 | H32: 1326 | I32: =G32-J32 -> 0 | J32: 8 | K32: 5 | L32: 0 | M32: 0 | N32: Sweetbox, Veatbox | O32: 1544-1122 | P32: www.cgv.co.kr | Q32: 36617
A33: 32 | B33: 경기도 | C33: 성남시 | D33: CGV 오리 | E33: 직영 | F33: 성남시 분당구 탄천상로 151번길 20 (구미동 159 월드쇼핑 4층) | G33: 10 | H33: 1571 | I33: =G33-J33 -> 0 | J33: 10 | K33: 5 | L33: 0 | M33: 0 | N33: Gold Class, CGV 아트하우스, Sweetbox, Screenx | O33: 1544-1122 | P33: www.cgv.co.kr | Q33: 36617
A34: 33 | B34: 경기도 | C34: 성남시 | D34: 롯데시네마 성남 | E34: 위탁 | F34: 성남시 중원구 성남대로 1136 (성남동 3499) | G34: 6 | H34: 667 | I34: 0 | J34: 6 | K34: 0 | L34: 0 | M34: 0 | N34: ~ | O34: 1544-8855 | P34: www.lottecinema.co.kr | Q34: 38715
A35: 34 | B35: 경기도 | C35: 성남시 | D35: 롯데시네마 성남신흥 | E35: 위탁 | F35: 성남시 수정구 산성대로 331 (신흥동2동 2463-4) | G35: 6 | H35: 1142 | I35: 0 | J35: 6 | K35: 0 | L35: 0 | M35: 0 | N35: ~ | O35: 1544-8855 | P35: www.lottecinema.co.kr | Q35: 39345
A36: 35 | B36: 경기도 | C36: 성남시 | D36: 메가박스 분당 | E36: 직영 | F36: 성남시 분당구 황새울로 32 (서현동 262-2) | G36: 6 | H36: 791 | I36: 0 | J36: 6 | K36: 3 | L36: 0 | M36: 0 | N36: Boutique M, Balcony M | O36: 1544-0070 | P36: www.megabox.co.kr | Q36: 37100 | R36: (구) 시네플라자
A37: 36 | B37: 경기도 | C37: 성남시 | D37: CGV 서현 | E37: 직영 | F37: 성남시 분당구 서현로 180번길 19 비전월드빌딩 1층 | G37: 4 | H37: 455 | I37: 0 | J37: 4 | K37: 0 | L37: 0 | M37: 0 | N37: ~ | O37: 1544-1122 | P37: www.cgv.co.kr | Q37: 41865
A38: 37 | B38: 경기도 | C38: 수원시 | D38: CGV 동수원 | E38: 직영 | F38: 수원시 팔달구 권광로 181, 7층 (인계동 113-11 12번지 7~10) | G38: 8 | H38: 1275 | I38: =G38-J38 -> 0 | J38: 8 | K38: 4 | L38: 0 | M38: 1 | N38: 4DX, CGV 아트하우스, ScreenX, Veatbox | O38: 1544-1122 | P38: www.cgv.co.kr | Q38: 38981
A39: 38 | B39: 경기도 | C39: 수원시 | D39: CGV 북수원 | E39: 직영 | F39: 수원시 장안구 경수대로 950, 4층 (조원동 893 아일렛타운 4층) | G39: 8 | H39: 1268 | I39: =G39-J39 -> 0 | J39: 8 | K39: 4 | L39: 0 | M39: 0 | N39: Sweetbox, Veatbox | O39: 1544-1122 | P39: www.cgv.co.kr | Q39: 38981
A40: 39 | B40: 경기도 | C40: 수원시 | D40: CGV 수원 | E40: 직영 | F40: 수원시 팔달구 덕영대로 924, 6층 (매산로 1가) | G40: 8 | H40: 2236 | I40: =G40-J40 -> 0 | J40: 8 | K40: 4 | L40: 1 | M40: 0 | N40: IMAX, Sweetbox, Veatbox, ScreenX | O40: 1544-1122 | P40: www.cgv.co.kr | Q40: 37300
...

Sheet 강원
A1: 번호 | B1: 광역단체 | C1: 기초단체 | D1: 영화관명 | E1: 대기업 운영 여부 | F1: 소재지 | G1: 총스크린수 | H1: 총좌석수 | I1: 필름 전용관수 | J1: 디지털 2D 상영관수 | K1: 3D 가능관수 | L1: IMAX 상영관 수 | M1: 4D 상영관수 | N1: 특별관 운영 여부 | O1: 전화번호(033) | P1: 홈페이지 | Q1: 개관일 | R1: 비고
A2: 1 | B2: 강원도 | C2: 강릉시 | D2: CGV 강릉 | E2: 직영 | F2: 강릉시 경강로 2120, 6층~8층 (옥천동 189) | G2: 8 | H2: 1295 | I2: 0 | J2: 8 | K2: 3 | L2: 0 | M2: 0 | N2: Sweetbox, ScreenX | O2: 1544-1122 | P2: www.cgv.co.kr | Q2: 41074
A3: 2 | B3: 강원도 | C3: 강릉시 | D3: 강릉독립예술극장 신영 | E3: ~ | F3: 강릉시 경강로 2100 (임당동 152-2) | G3: 1 | H3: 200 | I3: 0 | J3: 1 | K3: 0 | L3: 0 | M3: 0 | N3: ~ | O3: 645-7415 | P3: theque.tistory.com/ | Q3: 2012-00-00 | R3: (구)신영극장/2012년 개관
A4: 3 | B4: 강원도 | C4: 동해시 | D4: 롯데시네마 동해 | E4: 위탁 | F4: 동해시 한섬로 111-7 현진빌딩 5층 (천곡동) | G4: 5 | H4: 670 | I4: =G4-J4 -> 0 | J4: 5 | K4: 2 | L4: 0 | M4: 0 | N4: ~ | O4: 1544-8855 | P4: www.lottecinema.co.kr | Q4: 40078
A5: 4 | B5: 강원도 | C5: 속초시 | D5: 메가박스 속초 | E5: 위탁 | F5: 속초시 조양로142번길 20 (조양동 1506-1) | G5: 5 | H5: 714 | I5: 0 | J5: 5 | K5: 2 | L5: 0 | M5: 0 | N5: Table M관 | O5: 1544-0070 | P5: www.megabox.co.kr | Q5: 39874
A6: 5 | B6: 강원도 | C6: 원주시 | D6: 롯데시네마 남원주 | E6: 직영 | F6: 원주시 서원대로 396 (단구동 1511-2,3) | G6: 7 | H6: 1196 | I6: 0 | J6: 7 | K6: 3 | L6: 0 | M6: 0 | N6: ~ | O6: 1544-8855 | P6: www.lottecinema.co.kr | Q6: 38653
A7: 6 | B7: 강원도 | C7: 원주시 | D7: 메가박스 원주 | E7: 위탁 | F7: 원주시 서원대로 165-3 아트스페이스빌딩 6층 (단계동 873) | G7: 8 | H7: 901 | I7: =G7-J7 -> 0 | J7: 8 | K7: 3 | L7: 0 | M7: 0 | N7: ~ | O7: 1544-0070 | P7: www.megabox.co.kr | Q7: 39394
A8: 7 | B8: 강원도 | C8: 원주시 | D8: CGV 원주 | E8: 직영 | F8: 원주시 서원대로 171, 7층 (단계동) | G8: 10 | H8: 1870 | I8: 0 | J8: 10 | K8: 3 | L8: 0 | M8: 0 | N8: ~ | O8: 1544-1122 | P8: www.cgv.co.kr | Q8: 41158
A9: 8 | B9: 강원도 | C9: 춘천시 | D9: CGV 춘천 | E9: 직영 | F9: 춘천시 지석로 80, 3층~8층 (퇴계동 1017투탑시티 3층~8층) | G9: 12 | H9: 2099 | I9: =G9-J9 -> 0 | J9: 12 | K9: 5 | L9: 1 | M9: 0 | N9: Sweet Box, IMAX, Premium, ScreenX | O9: 1544-1122 | P9: www.cgv.co.kr | Q9: 39506
A10: 9 | B10: 강원도 | C10: 춘천시 | D10: CGV 춘천명동 | E10: 위탁 | F10: 춘천시 중앙로 3가 67 (조양동 144-3) | G10: 6 | H10: 698 | I10: 0 | J10: 6 | K10: 1 | L10: 0 | M10: 0 | N10: ~ | O10: 1544-1122 | P10: www.cgv.co.kr | Q10: 41760 | R10: (구)프리머스 춘천
A11: 10 | B11: 강원도 | C11: 홍천군 | D11: 홍천시네마 | E11: ~ | F11: 홍천군 홍천읍 연봉중앙로 11-8 | G11: 2 | H11: 98 | I11: 0 | J11: 2 | K11: 1 | L11: 0 | M11: 0 | N11: ~ | O11: 433-7053 | P11: hongcheon.ccine.co.kr | Q11: 41737
A12: 11 | B12: 강원도 | C12: 화천군 | D12: 산천어시네마 | E12: ~ | F12: 화천군 화천읍 상승로2길 25-10, 2층 | G12: 1 | H12: 125 | I12: 0 | J12: 1 | K12: 1 | L12: 0 | M12: 0 | N12: ~ | O12: 441-7053 | P12: www.sancheoneocinema.co.kr | Q12: 41993

Sheet 충북
A1: 번호 | B1: 광역단체 | C1: 기초단체 | D1: 영화관명 | E1: 대기업 운영 여부 | F1: 소재지 | G1: 총스크린수 | H1: 총좌석수 | I1: 필름 전용관수 | J1: 디지털 2D 상영관수 | K1: 3D 가능관수 | L1: IMAX 상영관 수 | M1: 4D 상영관수 | N1: 특별관 운영 여부 | O1: 전화번호(043) | P1: 홈페이지 | Q1: 개관일 | R1: 비고
A2: 1 | B2: 충청북도 | C2: 제천시 | D2: 메가박스 제천 | E2: 위탁 | F2: 제천시 의병대로 18길 1 (남천동 1145) | G2: 7 | H2: 1200 | I2: =G2-J2 -> 0 | J2: 7 | K2: 3 | L2: 0 | M2: 0 | N2: ~ | O2: 1544-0070 | P2: www.megabox.co.kr | Q2: 40848 | R2: (구)제천TTC7
A3: 2 | B3: 충청북도 | C3: 청주시 | D3: CGV 청주(북문) | E3: 위탁 | F3: 청주시 상당구 상당로 81번길 33 (북문로1가 170-1) | G3: 8 | H3: 1239 | I3: 0 | J3: 8 | K3: 1 | L3: 0 | M3: 0 | N3: ~ | O3: 1544-1122 | P3: www.cgv.co.kr | Q3: 39653
A4: 3 | B4: 충청북도 | C4: 청주시 | D4: CGV 청주(서문) | E4: 위탁 | F4: 청주시 상당구 상당로 81번길 63 (서문동 29-2) | G4: 10 | H4: 1996 | I4: 0 | J4: 10 | K4: 4 | L4: 0 | M4: 0 | N4: ~ | O4: 1544-1122 | P4: www.cgv.co.kr | Q4: 39364
A5: 4 | B5: 충청북도 | C5: 청주시 | D5: CGV 청주지웰시티 | E5: 직영 | F5: 청주시 흥덕구 대농로 47-1 | G5: 8 | H5: 1707 | I5: 0 | J5: 8 | K5: 3 | L5: 0 | M5: 0 | N5: Sweetbox | O5: 1544-1122 | P5: www.cgv.co.kr | Q5: 41753
A6: 5 | B6: 충청북도 | C6: 청주시 | D6: CGV 청주터미널 | E6: 위탁 | F6: 청주시 흥덕구 흥덕구2순환로 1233 (가경동 1233 드림플러스 8층) | G6: 8 | H6: 1292 | I6: 0 | J6: 8 | K6: 0 | L6: 0 | M6: 0 | N6: ~ | O6: 1544-1122 | P6: www.cgv.co.kr | Q6: 41628 | R6: (구)프리머스 청주
A7: 6 | B7: 충청북도 | C7: 청주시 | D7: SFX시네마 | E7: ~ | F7: 청주시 상당구 충청대로 114 (율량동 500-3) | G7: 11 | H7: 1672 | I7: 0 | J7: 11 | K7: 1 | L7: 0 | M7: 0 | N7: ~ | O7: 290-1500 | P7: www.isfx.co.kr | Q7: 38862
A8: 7 | B8: 충청북도 | C8: 청주시 | D8: 롯데시네마 서청주 | E8: 직영 | F8: 청주시 흥덕구 2순환로 1004 (비하동 332-1) | G8: 6 | H8: 1286 | I8: 0 | J8: 6 | K8: 3 | L8: 0 | M8: 1 | N8: 수퍼4D, 수퍼사운드 | O8: 1544-8855 | P8: www.lottecinema.co.kr | Q8: 41207
A9: 8 | B9: 충청북도 | C9: 청주시 | D9: 롯데시네마 청주 | E9: 직영 | F9: 청주시 상당구 성안로 13 씨유멀티플렉스 3층 (북문로1가 90-1) | G9: 8 | H9: 1402 | I9: =G9-J9 -> 0 | J9: 8 | K9: 4 | L9: 0 | M9: 0 | N9: 아르떼 | O9: 1544-8855 | P9: www.lottecinema.co.kr | Q9: 39784
A10: 9 | B10: 충청북도 | C10: 청주시 | D10: 롯데시네마 청주충대 | E10: 위탁 | F10: 청주시 흥덕구 1순환로 682 (사창동 488) | G10: 4 | H10: 497 | I10: 0 | J10: 4 | K10: 1 | L10: 0 | M10: 0 | N10: ~ | O10: 1544-8855 | P10: www.lottecinema.co.kr | Q10: 41598 | R10: (구)키노피아
A11: 10 | B11: 충청북도 | C11: 충주시 | D11: 메가박스 충주 | E11: 위탁 | F11: 충주시 성서3길 19 (성서동 273) | G11: 10 | H11: 1757 | I11: 0 | J11: 10 | K11: 3 | L11: 0 | M11: 0 | N11: ~ | O11: 1544-0070 | P11: www.megabox.co.kr | Q11: 41262 | R11: (구)충주TTC/2012년 메가박스 충주로 전환

Sheet 충남
A1: 번호 | B1: 광역단체 | C1: 기초단체 | D1: 영화관명 | E1: 대기업 운영 여부 | F1: 소재지 | G1: 총스크린수 | H1: 총좌석수 | I1: 필름 전용관수 | J1: 디지털 2D 상영관수 | K1: 3D 가능관수 | L1: IMAX 상영관 수 | M1: 4D 상영관수 | N1: 특별관 운영 여부 | O1: 전화번호(041) | P1: 홈페이지 | Q1: 개관일 | R1: 비고
A2: 1 | B2: 충청남도 | C2: 공주시 | D2: 메가박스 공주 | E2: 위탁 | F2: 공주시 흑수골길 12 (신관동 248-3) | G2: 7 | H2: 802 | I2: =G2-J2 -> 0 | J2: 7 | K2: 3 | L2: 0 | M2: 0 | N2: ~ | O2: 1544-0070 | P2: www.megabox.co.kr | Q2: 38380
A3: 2 | B3: 충청남도 | C3: 논산시 | D3: 논산시네마 | E3: ~ | F3: 논산시 해월로 167번길 8 (반월동 68-19) | G3: 5 | H3: 616 | I3: 0 | J3: 5 | K3: 0 | M3: 0 | N3: ~ | O3: 733-2004 | Q3: 2003-09-10
A4: 3 | B4: 충청남도 | C4: 당진시 | D4: 당진시네마 | E4: ~ | F4: 당진시 당진중앙2로 76 (읍내동 543-39) | G4: 3 | H4: 313 | I4: 0 | J4: 3 | K4: 0 | L4: 0 | M4: 0 | N4: ~ | O4: 355-2116 | P4: djt.movieplus.or.kr | Q4: 2008-02-28
A5: 4 | B5: 충청남도 | C5: 당진시 | D5: CGV 당진 | E5: 위탁 | F5: 당진시 우두1로 88 (읍내동) | G5: 7 | H5: 1076 | I5: 0 | J5: 7 | K5: 7 | L5: 0 | M5: 0 | N5: Sweetbox | O5: 1544-1122 | P5: www.cgv.co.kr | Q5: 41979
A6: 5 | B6: 충청남도 | C6: 부여군 | D6: 금성시네마 | E6: ~ | F6: 부여군 부여읍 사비로 100번길 12 (구아리 209-1) | G6: 2 | H6: 175 | I6: 0 | J6: 2 | K6: 1 | L6: 0 | M6: 0 | N6: ~ | O6: 833-9999 | Q6: 39854
A7: 6 | B7: 충청남도 | C7: 서산시 | D7: 롯데시네마 서산 | E7: 위탁 | F7: 서산시 율지18로 38 (동문동 193-1) | G7: 6 | H7: 1076 | I7: =G7-J7 -> 0 | J7: 6 | K7: 6 | L7: 0 | M7: 0 | N7: ~ | O7: 1544-8855 | P7: www.lottecinema.co.kr | Q7: 40658
A8: 7 | B8: 충청남도 | C8: 세종시 | D8: 메가박스 세종 | E8: 위탁 | F8: 세종시 조치원읍 새내로 122 (교리 24-1) | G8: 5 | H8: 738 | I8: =G8-J8 -> 0 | J8: 5 | K8: 2 | L8: 0 | M8: 0 | N8: ~ | O8: 1544-0070 | P8: www.megabox.co.kr | Q8: 40611 | R8: (구)메가박스 조치원
A9: 8 | B9: 충청남도 | C9: 아산시 | D9: 롯데시네마 아산터미널 | E9: 직영 | F9: 아산시 번영로 225 | G9: 6 | H9: 964 | I9: 0 | J9: 6 | K9: 2 | L9: 0 | M9: 0 | N9: ~ | O9: 1544-8855 | P9: www.lottecinema.co.kr | Q9: 41663
A10: 9 | B10: 충청남도 | C10: 천안시 | D10: CGV 천안 | E10: 직영 | F10: 천안시 동남구 명동길 47, 5층 (대흥동102-10번지 5층) | G10: 8 | H10: 1118 | I10: =G10-J10 -> 0 | J10: 8 | K10: 4 | L10: 0 | M10: 0 | N10: Sweetbox | O10: 1544-1122 | P10: www.cgv.co.kr | Q10: 39172
A11: 10 | B11: 충청남도 | C11: 천안시 | D11: CGV 천안펜타포트 | E11: 직영 | F11: 천안시 서북구 공원로 196, 5층 (불당동 1289 펜타포트 주상복합상가 5층) | G11: 10 | H11: 1190 | I11: 0 | J11: 10 | K11: 6 | L11: 0 | M11: 1 | N11: 4DX, Sweetbox, ScreenX, Veatbox, CGV 아트하우스 | O11: 1544-1122 | P11: www.cgv.co.kr | Q11: 41334
A12: 11 | B12: 충청남도 | C12: 천안시 | D12: 메가박스 천안 | E12: 직영 | F12: 천안시 서북구 1공단1길 52 센트하임 3층 (두정동 68-1) | G12: 9 | H12: 1290 | I12: 0 | J12: 9 | K12: 3 | L12: 0 | M12: 0 | N12: 프리미엄 | O12: 1544-0070 | P12: www.megabox.co.kr | Q12: 38561
A13: 12 | B13: 충청남도 | C13: 천안시 | D13: 야우리멀티플렉스 | E13: ~ | F13: 천안시 만남로 43 (동남구 354-1) | G13: 10 | H13: 1725 | I13: 0 | J13: 10 | K13: 3 | L13: 0 | M13: 0 | N13: 15관 프리미엄관 | O13: 640-6200 | P13: www.yawooricinema.com | Q13: 37155
A14: 13 | B14: 충청남도 | C14: 홍성군 | D14: CGV 홍성 | E14: 위탁 | F14: 홍성군 홍성읍 고암리 1042 | G14: 4 | H14: 568 | I14: =G14-J14 -> 0 | J14: 4 | K14: 2 | L14: 0 | M14: 0 | N14: Sweetbox | O14: 1544-1122 | P14: www.cgv.co.kr | Q14: 40899
A17: 2014년 휴폐관 극장
A18: 1 | B18: 충청남도 | C18: 당진군 | D18: 키노키노 | E18: ~ | F18: 당진군 당진읍 읍내리 253-8 | G18: 2 | H18: 368 | I18: 0 | J18: 2 | K18: 0 | L18: 0 | M18: 0 | N18: ~ | O18: 356-8300 | Q18: 2009-07-01 | R18: 2014.11 폐관 / 2015.1.1. 조이앤시네마로 재개관 예정
A19: 2 | B19: 충청남도 | C19: 보령시 | D19: 롯데시네마 보령 | E19: 위탁 | F19: 보령시 대천동 대흥로 51 | G19: 7 | H19: 1067 | I19: 0 | J19: 7 | K19: 2 | L19: 0 | M19: 0 | N19: ~ | O19: 1544-8855 | P19: www.lottecinema.co.kr | Q19: 41101 | R19: 2014.8.31 영업종료

Sheet 전북
A1: 번호 | B1: 광역단체 | C1: 기초단체 | D1: 영화관명 | E1: 대기업 운영 여부 | F1: 소재지 | G1: 총스크린수 | H1: 총좌석수 | I1: 필름 전용관수 | J1: 디지털 2D 상영관수 | K1: 3D 가능관수 | L1: IMAX 상영관 수 | M1: 4D 상영관수 | N1: 특별관 운영 여부 | O1: 전화번호(063) | P1: 홈페이지 | Q1: 개관일 | R1: 비고
A2: 1 | B2: 전라북도 | C2: 군산시 | D2: CGV 군산 | E2: 위탁 | F2: 군산시 백토로 198 (나운동 114-34) | G2: 7 | H2: 1027 | I2: =G2-J2 -> 0 | J2: 7 | K2: 0 | L2: 0 | M2: 0 | N2: ~ | O2: 1544-1122 | P2: www.cgv.co.kr | Q2: 39779 | R2: 08.11.27 CGV로 재개관
A3: 2 | B3: 전라북도 | C3: 군산시 | D3: 롯데시네마 군산 | E3: 위탁 | F3: 군산시 백토로 166 (나운동 124-4) | G3: 5 | H3: 975 | I3: =G3-J3 -> 0 | J3: 5 | K3: 2 | L3: 0 | M3: 0 | N3: ~ | O3: 1544-8855 | P3: www.lottecinema.co.kr | Q3: 38834
A4: 3 | B4: 전라북도 | C4: 김제시 | D4: 지평선시네마 | E4: ~ | F4: 김제시 도작로 224-32 (검산동 산 62-1) | G4: 2 | H4: 99 | I4: 0 | J4: 2 | K4: 1 | L4: 0 | M4: 0 | N4: ~ | O4: 547-1501 | Q4: 41512
A5: 4 | B5: 전라북도 | C5: 남원시 | D5: 메가박스 남원 | E5: 위탁 | F5: 남원시 향단로 26 (쌍교동82-1) | G5: 4 | H5: 615 | I5: 0 | J5: 4 | K5: 0 | L5: 0 | M5: 0 | N5: ~ | O5: 1544-0070 | P5: www.megabox.co.kr | Q5: 39625
A6: 5 | B6: 전라북도 | C6: 무주군 | D6: 무주산골영화관 | E6: ~ | F6: 무주군 무주읍 한풍루로 326-17 무주예체문화관 2층 | G6: 2 | H6: 98 | I6: 0 | J6: 2 | K6: 1 | L6: 0 | M6: 0 | N6: ~ | O6: 322-7053 | P6: movie.muju.go.kr | Q6: 41810
A7: 6 | B7: 전라북도 | C7: 부안군 | D7: 마실영화관 | E7: ~ | F7: 부안군 부안읍 예술회관길 11 | G7: 2 | H7: 99 | I7: 0 | J7: 2 | K7: 1 | L7: 0 | M7: 0 | N7: ~ | O7: 582-1228 | P7: www.buanmasilcinema.co.kr | Q7: 41871
A8: 7 | B8: 전라북도 | C8: 완주군 | D8: 완주 휴 시네마 | E8: ~ | F8: 완주군 봉동읍 둔산3로 94 | G8: 2 | H8: 91 | I8: 0 | J8: 2 | K8: 1 | L8: 0 | M8: 0 | N8: ~ | O8: 263-9012 | P8: wanjumovie.kr | Q8: 41920
A9: 8 | B9: 전라북도 | C9: 익산시 | D9: CGV 익산 | E9: 위탁 | F9: 익산시 무왕로 1052, 3층~5층 (영등동 149-1) | G9: 9 | H9: 1325 | I9: 0 | J9: 9 | K9: 4 | L9: 0 | M9: 0 | N9: Sweetbox | O9: 1544-1122 | P9: www.cgv.co.kr | Q9: 38141
A10: 9 | B10: 전라북도 | C10: 임실군 | D10: 작은별 영화관 | E10: ~ | F10: 임실군 임실읍 호국로 1703 (이도리 277 임실군민회관) | G10: 2 | H10: 94 | I10: 0 | J10: 2 | K10: 1 | L10: 0 | M10: 0 | N10: ~ | O10: 644-7050 | P10: imsil.ccine.co.kr | Q10: 2013-00-00
A11: 10 | B11: 전라북도 | C11: 장수군 | D11: 한누리시네마 | E11: ~ | F11: 장수군 장수읍 한누리로 393 (두산리 472) | G11: 2 | H11: 90 | I11: =G11-J11 -> 0 | J11: 2 | K11: 1 | L11: 0 | M11: 0 | N11: ~ | O11: 352-7050 | P11: hannuri.ccine.co.kr | Q11: 40507
A12: 11 | B12: 전라북도 | C12: 전주시 | D12: CGV 전주 | E12: 위탁 | F12: 전주시 완산구 전주객사3길 74-25 (고사동 288-2) | G12: 6 | H12: 1192 | I12: =G12-J12 -> 0 | J12: 6 | K12: 1 | L12: 0 | M12: 0 | N12: ~ | O12: 1544-1122 | P12: www.cgv.co.kr | Q12: 37931 | R12: (구)피카디리극장
A13: 12 | B13: 전라북도 | C13: 전주시 | D13: CGV 전주효자 | E13: 직영 | F13: 전주시 완산구 용머리로 45 (Mall of Hyoja 2층) | G13: 7 | H13: 1795 | I13: 0 | J13: 7 | K13: 3 | L13: 1 | M13: 0 | N13: IMAX | O13: 1544-1122 | P13: www.cgv.co.kr | Q13: 41879
A14: 13 | B14: 전라북도 | C14: 전주시 | D14: 롯데시네마 전주(롯데백화점) | E14: 직영 | F14: 전주시 완산구 온고을로 2 (서신동 971) | G14: 8 | H14: 1626 | I14: =G14-J14 -> 0 | J14: 8 | K14: 6 | L14: 0 | M14: 0 | N14: ~ | O14: 1544-8855 | P14: www.lottecinema.co.kr | Q14: 38135
A15: 14 | B15: 전라북도 | C15: 전주시 | D15: 롯데시네마 전주평화 | E15: 직영 | F15: 전주시 완산구 백제대로 10 (평화동 1가 604-1) | G15: 6 | H15: 922 | I15: 0 | J15: 6 | K15: 3 | L15: 0 | M15: 0 | N15: ~ | O15: 1544-8855 | P15: www.lottecinema.co.kr | Q15: 41179
A16: 15 | B16: 전라북도 | C16: 전주시 | D16: 메가박스 송천 | E16: 위탁 | F16: 전주시 덕진구 동부대로 1215 (송천동 2가 661-15) | G16: 8 | H16: 1225 | I16: =G16-J16 -> 0 | J16: 8 | K16: 6 | L16: 0 | M16: 0 | N16: ~ | O16: 1544-0070 | P16: www.megabox.co.kr | Q16: 39139
